2025-03-05 18:58:14 - root - ERROR - Sistema de logging inicializado (console: ERROR, arquivo: ERROR)
2025-03-05 18:58:40 - root - ERROR - Sistema de logging inicializado (console: ERROR, arquivo: ERROR)
2025-03-05 18:58:43 - telegram.ext.Updater - ERROR - Error while getting Updates: Conflict: terminated by other getUpdates request; make sure that only one bot instance is running
2025-03-05 18:58:43 - telegram.ext.Updater - ERROR - Exception happened while polling for updates.
Traceback (most recent call last):
  File "/Users/alexandresimasmaciel/Library/Python/3.9/lib/python/site-packages/telegram/ext/_updater.py", line 688, in _network_loop_retry
    if not await action_cb():
  File "/Users/alexandresimasmaciel/Library/Python/3.9/lib/python/site-packages/telegram/ext/_updater.py", line 384, in polling_action_cb
    raise exc
  File "/Users/alexandresimasmaciel/Library/Python/3.9/lib/python/site-packages/telegram/ext/_updater.py", line 373, in polling_action_cb
    updates = await self.bot.get_updates(
  File "/Users/alexandresimasmaciel/Library/Python/3.9/lib/python/site-packages/telegram/ext/_extbot.py", line 558, in get_updates
    updates = await super().get_updates(
  File "/Users/alexandresimasmaciel/Library/Python/3.9/lib/python/site-packages/telegram/_bot.py", line 525, in decorator
    result = await func(self, *args, **kwargs)  # skipcq: PYL-E1102
  File "/Users/alexandresimasmaciel/Library/Python/3.9/lib/python/site-packages/telegram/_bot.py", line 3584, in get_updates
    await self._post(
  File "/Users/alexandresimasmaciel/Library/Python/3.9/lib/python/site-packages/telegram/_bot.py", line 613, in _post
    return await self._do_post(
  File "/Users/alexandresimasmaciel/Library/Python/3.9/lib/python/site-packages/telegram/ext/_extbot.py", line 340, in _do_post
    return await super()._do_post(
  File "/Users/alexandresimasmaciel/Library/Python/3.9/lib/python/site-packages/telegram/_bot.py", line 641, in _do_post
    return await request.post(
  File "/Users/alexandresimasmaciel/Library/Python/3.9/lib/python/site-packages/telegram/request/_baserequest.py", line 200, in post
    result = await self._request_wrapper(
  File "/Users/alexandresimasmaciel/Library/Python/3.9/lib/python/site-packages/telegram/request/_baserequest.py", line 381, in _request_wrapper
    raise Conflict(message)
telegram.error.Conflict: Conflict: terminated by other getUpdates request; make sure that only one bot instance is running
2025-03-05 18:58:47 - telegram.ext.Updater - ERROR - Error while getting Updates: Conflict: terminated by other getUpdates request; make sure that only one bot instance is running
2025-03-05 18:58:47 - telegram.ext.Updater - ERROR - Exception happened while polling for updates.
Traceback (most recent call last):
  File "/Users/alexandresimasmaciel/Library/Python/3.9/lib/python/site-packages/telegram/ext/_updater.py", line 688, in _network_loop_retry
    if not await action_cb():
  File "/Users/alexandresimasmaciel/Library/Python/3.9/lib/python/site-packages/telegram/ext/_updater.py", line 384, in polling_action_cb
    raise exc
  File "/Users/alexandresimasmaciel/Library/Python/3.9/lib/python/site-packages/telegram/ext/_updater.py", line 373, in polling_action_cb
    updates = await self.bot.get_updates(
  File "/Users/alexandresimasmaciel/Library/Python/3.9/lib/python/site-packages/telegram/ext/_extbot.py", line 558, in get_updates
    updates = await super().get_updates(
  File "/Users/alexandresimasmaciel/Library/Python/3.9/lib/python/site-packages/telegram/_bot.py", line 525, in decorator
    result = await func(self, *args, **kwargs)  # skipcq: PYL-E1102
  File "/Users/alexandresimasmaciel/Library/Python/3.9/lib/python/site-packages/telegram/_bot.py", line 3584, in get_updates
    await self._post(
  File "/Users/alexandresimasmaciel/Library/Python/3.9/lib/python/site-packages/telegram/_bot.py", line 613, in _post
    return await self._do_post(
  File "/Users/alexandresimasmaciel/Library/Python/3.9/lib/python/site-packages/telegram/ext/_extbot.py", line 340, in _do_post
    return await super()._do_post(
  File "/Users/alexandresimasmaciel/Library/Python/3.9/lib/python/site-packages/telegram/_bot.py", line 641, in _do_post
    return await request.post(
  File "/Users/alexandresimasmaciel/Library/Python/3.9/lib/python/site-packages/telegram/request/_baserequest.py", line 200, in post
    result = await self._request_wrapper(
  File "/Users/alexandresimasmaciel/Library/Python/3.9/lib/python/site-packages/telegram/request/_baserequest.py", line 381, in _request_wrapper
    raise Conflict(message)
telegram.error.Conflict: Conflict: terminated by other getUpdates request; make sure that only one bot instance is running
2025-03-05 18:58:48 - telegram.ext.Updater - ERROR - Error while getting Updates: Conflict: terminated by other getUpdates request; make sure that only one bot instance is running
2025-03-05 18:58:48 - telegram.ext.Updater - ERROR - Exception happened while polling for updates.
Traceback (most recent call last):
  File "/Users/alexandresimasmaciel/Library/Python/3.9/lib/python/site-packages/telegram/ext/_updater.py", line 688, in _network_loop_retry
    if not await action_cb():
  File "/Users/alexandresimasmaciel/Library/Python/3.9/lib/python/site-packages/telegram/ext/_updater.py", line 384, in polling_action_cb
    raise exc
  File "/Users/alexandresimasmaciel/Library/Python/3.9/lib/python/site-packages/telegram/ext/_updater.py", line 373, in polling_action_cb
    updates = await self.bot.get_updates(
  File "/Users/alexandresimasmaciel/Library/Python/3.9/lib/python/site-packages/telegram/ext/_extbot.py", line 558, in get_updates
    updates = await super().get_updates(
  File "/Users/alexandresimasmaciel/Library/Python/3.9/lib/python/site-packages/telegram/_bot.py", line 525, in decorator
    result = await func(self, *args, **kwargs)  # skipcq: PYL-E1102
  File "/Users/alexandresimasmaciel/Library/Python/3.9/lib/python/site-packages/telegram/_bot.py", line 3584, in get_updates
    await self._post(
  File "/Users/alexandresimasmaciel/Library/Python/3.9/lib/python/site-packages/telegram/_bot.py", line 613, in _post
    return await self._do_post(
  File "/Users/alexandresimasmaciel/Library/Python/3.9/lib/python/site-packages/telegram/ext/_extbot.py", line 340, in _do_post
    return await super()._do_post(
  File "/Users/alexandresimasmaciel/Library/Python/3.9/lib/python/site-packages/telegram/_bot.py", line 641, in _do_post
    return await request.post(
  File "/Users/alexandresimasmaciel/Library/Python/3.9/lib/python/site-packages/telegram/request/_baserequest.py", line 200, in post
    result = await self._request_wrapper(
  File "/Users/alexandresimasmaciel/Library/Python/3.9/lib/python/site-packages/telegram/request/_baserequest.py", line 381, in _request_wrapper
    raise Conflict(message)
telegram.error.Conflict: Conflict: terminated by other getUpdates request; make sure that only one bot instance is running
2025-03-05 18:58:53 - telegram.ext.Updater - ERROR - Error while getting Updates: Conflict: terminated by other getUpdates request; make sure that only one bot instance is running
2025-03-05 18:58:53 - telegram.ext.Updater - ERROR - Exception happened while polling for updates.
Traceback (most recent call last):
  File "/Users/alexandresimasmaciel/Library/Python/3.9/lib/python/site-packages/telegram/ext/_updater.py", line 688, in _network_loop_retry
    if not await action_cb():
  File "/Users/alexandresimasmaciel/Library/Python/3.9/lib/python/site-packages/telegram/ext/_updater.py", line 384, in polling_action_cb
    raise exc
  File "/Users/alexandresimasmaciel/Library/Python/3.9/lib/python/site-packages/telegram/ext/_updater.py", line 373, in polling_action_cb
    updates = await self.bot.get_updates(
  File "/Users/alexandresimasmaciel/Library/Python/3.9/lib/python/site-packages/telegram/ext/_extbot.py", line 558, in get_updates
    updates = await super().get_updates(
  File "/Users/alexandresimasmaciel/Library/Python/3.9/lib/python/site-packages/telegram/_bot.py", line 525, in decorator
    result = await func(self, *args, **kwargs)  # skipcq: PYL-E1102
  File "/Users/alexandresimasmaciel/Library/Python/3.9/lib/python/site-packages/telegram/_bot.py", line 3584, in get_updates
    await self._post(
  File "/Users/alexandresimasmaciel/Library/Python/3.9/lib/python/site-packages/telegram/_bot.py", line 613, in _post
    return await self._do_post(
  File "/Users/alexandresimasmaciel/Library/Python/3.9/lib/python/site-packages/telegram/ext/_extbot.py", line 340, in _do_post
    return await super()._do_post(
  File "/Users/alexandresimasmaciel/Library/Python/3.9/lib/python/site-packages/telegram/_bot.py", line 641, in _do_post
    return await request.post(
  File "/Users/alexandresimasmaciel/Library/Python/3.9/lib/python/site-packages/telegram/request/_baserequest.py", line 200, in post
    result = await self._request_wrapper(
  File "/Users/alexandresimasmaciel/Library/Python/3.9/lib/python/site-packages/telegram/request/_baserequest.py", line 381, in _request_wrapper
    raise Conflict(message)
telegram.error.Conflict: Conflict: terminated by other getUpdates request; make sure that only one bot instance is running
2025-03-05 18:58:55 - telegram.ext.Updater - ERROR - Error while getting Updates: Conflict: terminated by other getUpdates request; make sure that only one bot instance is running
2025-03-05 18:58:55 - telegram.ext.Updater - ERROR - Exception happened while polling for updates.
Traceback (most recent call last):
  File "/Users/alexandresimasmaciel/Library/Python/3.9/lib/python/site-packages/telegram/ext/_updater.py", line 688, in _network_loop_retry
    if not await action_cb():
  File "/Users/alexandresimasmaciel/Library/Python/3.9/lib/python/site-packages/telegram/ext/_updater.py", line 384, in polling_action_cb
    raise exc
  File "/Users/alexandresimasmaciel/Library/Python/3.9/lib/python/site-packages/telegram/ext/_updater.py", line 373, in polling_action_cb
    updates = await self.bot.get_updates(
  File "/Users/alexandresimasmaciel/Library/Python/3.9/lib/python/site-packages/telegram/ext/_extbot.py", line 558, in get_updates
    updates = await super().get_updates(
  File "/Users/alexandresimasmaciel/Library/Python/3.9/lib/python/site-packages/telegram/_bot.py", line 525, in decorator
    result = await func(self, *args, **kwargs)  # skipcq: PYL-E1102
  File "/Users/alexandresimasmaciel/Library/Python/3.9/lib/python/site-packages/telegram/_bot.py", line 3584, in get_updates
    await self._post(
  File "/Users/alexandresimasmaciel/Library/Python/3.9/lib/python/site-packages/telegram/_bot.py", line 613, in _post
    return await self._do_post(
  File "/Users/alexandresimasmaciel/Library/Python/3.9/lib/python/site-packages/telegram/ext/_extbot.py", line 340, in _do_post
    return await super()._do_post(
  File "/Users/alexandresimasmaciel/Library/Python/3.9/lib/python/site-packages/telegram/_bot.py", line 641, in _do_post
    return await request.post(
  File "/Users/alexandresimasmaciel/Library/Python/3.9/lib/python/site-packages/telegram/request/_baserequest.py", line 200, in post
    result = await self._request_wrapper(
  File "/Users/alexandresimasmaciel/Library/Python/3.9/lib/python/site-packages/telegram/request/_baserequest.py", line 381, in _request_wrapper
    raise Conflict(message)
telegram.error.Conflict: Conflict: terminated by other getUpdates request; make sure that only one bot instance is running
2025-03-05 18:59:00 - telegram.ext.Updater - ERROR - Error while getting Updates: Conflict: terminated by other getUpdates request; make sure that only one bot instance is running
2025-03-05 18:59:00 - telegram.ext.Updater - ERROR - Exception happened while polling for updates.
Traceback (most recent call last):
  File "/Users/alexandresimasmaciel/Library/Python/3.9/lib/python/site-packages/telegram/ext/_updater.py", line 688, in _network_loop_retry
    if not await action_cb():
  File "/Users/alexandresimasmaciel/Library/Python/3.9/lib/python/site-packages/telegram/ext/_updater.py", line 384, in polling_action_cb
    raise exc
  File "/Users/alexandresimasmaciel/Library/Python/3.9/lib/python/site-packages/telegram/ext/_updater.py", line 373, in polling_action_cb
    updates = await self.bot.get_updates(
  File "/Users/alexandresimasmaciel/Library/Python/3.9/lib/python/site-packages/telegram/ext/_extbot.py", line 558, in get_updates
    updates = await super().get_updates(
  File "/Users/alexandresimasmaciel/Library/Python/3.9/lib/python/site-packages/telegram/_bot.py", line 525, in decorator
    result = await func(self, *args, **kwargs)  # skipcq: PYL-E1102
  File "/Users/alexandresimasmaciel/Library/Python/3.9/lib/python/site-packages/telegram/_bot.py", line 3584, in get_updates
    await self._post(
  File "/Users/alexandresimasmaciel/Library/Python/3.9/lib/python/site-packages/telegram/_bot.py", line 613, in _post
    return await self._do_post(
  File "/Users/alexandresimasmaciel/Library/Python/3.9/lib/python/site-packages/telegram/ext/_extbot.py", line 340, in _do_post
    return await super()._do_post(
  File "/Users/alexandresimasmaciel/Library/Python/3.9/lib/python/site-packages/telegram/_bot.py", line 641, in _do_post
    return await request.post(
  File "/Users/alexandresimasmaciel/Library/Python/3.9/lib/python/site-packages/telegram/request/_baserequest.py", line 200, in post
    result = await self._request_wrapper(
  File "/Users/alexandresimasmaciel/Library/Python/3.9/lib/python/site-packages/telegram/request/_baserequest.py", line 381, in _request_wrapper
    raise Conflict(message)
telegram.error.Conflict: Conflict: terminated by other getUpdates request; make sure that only one bot instance is running
2025-03-05 18:59:03 - telegram.ext.Updater - ERROR - Error while getting Updates: Conflict: terminated by other getUpdates request; make sure that only one bot instance is running
2025-03-05 18:59:03 - telegram.ext.Updater - ERROR - Exception happened while polling for updates.
Traceback (most recent call last):
  File "/Users/alexandresimasmaciel/Library/Python/3.9/lib/python/site-packages/telegram/ext/_updater.py", line 688, in _network_loop_retry
    if not await action_cb():
  File "/Users/alexandresimasmaciel/Library/Python/3.9/lib/python/site-packages/telegram/ext/_updater.py", line 384, in polling_action_cb
    raise exc
  File "/Users/alexandresimasmaciel/Library/Python/3.9/lib/python/site-packages/telegram/ext/_updater.py", line 373, in polling_action_cb
    updates = await self.bot.get_updates(
  File "/Users/alexandresimasmaciel/Library/Python/3.9/lib/python/site-packages/telegram/ext/_extbot.py", line 558, in get_updates
    updates = await super().get_updates(
  File "/Users/alexandresimasmaciel/Library/Python/3.9/lib/python/site-packages/telegram/_bot.py", line 525, in decorator
    result = await func(self, *args, **kwargs)  # skipcq: PYL-E1102
  File "/Users/alexandresimasmaciel/Library/Python/3.9/lib/python/site-packages/telegram/_bot.py", line 3584, in get_updates
    await self._post(
  File "/Users/alexandresimasmaciel/Library/Python/3.9/lib/python/site-packages/telegram/_bot.py", line 613, in _post
    return await self._do_post(
  File "/Users/alexandresimasmaciel/Library/Python/3.9/lib/python/site-packages/telegram/ext/_extbot.py", line 340, in _do_post
    return await super()._do_post(
  File "/Users/alexandresimasmaciel/Library/Python/3.9/lib/python/site-packages/telegram/_bot.py", line 641, in _do_post
    return await request.post(
  File "/Users/alexandresimasmaciel/Library/Python/3.9/lib/python/site-packages/telegram/request/_baserequest.py", line 200, in post
    result = await self._request_wrapper(
  File "/Users/alexandresimasmaciel/Library/Python/3.9/lib/python/site-packages/telegram/request/_baserequest.py", line 381, in _request_wrapper
    raise Conflict(message)
telegram.error.Conflict: Conflict: terminated by other getUpdates request; make sure that only one bot instance is running
2025-03-05 18:59:06 - telegram.ext.Updater - ERROR - Error while getting Updates: Conflict: terminated by other getUpdates request; make sure that only one bot instance is running
2025-03-05 18:59:06 - telegram.ext.Updater - ERROR - Exception happened while polling for updates.
Traceback (most recent call last):
  File "/Users/alexandresimasmaciel/Library/Python/3.9/lib/python/site-packages/telegram/ext/_updater.py", line 688, in _network_loop_retry
    if not await action_cb():
  File "/Users/alexandresimasmaciel/Library/Python/3.9/lib/python/site-packages/telegram/ext/_updater.py", line 384, in polling_action_cb
    raise exc
  File "/Users/alexandresimasmaciel/Library/Python/3.9/lib/python/site-packages/telegram/ext/_updater.py", line 373, in polling_action_cb
    updates = await self.bot.get_updates(
  File "/Users/alexandresimasmaciel/Library/Python/3.9/lib/python/site-packages/telegram/ext/_extbot.py", line 558, in get_updates
    updates = await super().get_updates(
  File "/Users/alexandresimasmaciel/Library/Python/3.9/lib/python/site-packages/telegram/_bot.py", line 525, in decorator
    result = await func(self, *args, **kwargs)  # skipcq: PYL-E1102
  File "/Users/alexandresimasmaciel/Library/Python/3.9/lib/python/site-packages/telegram/_bot.py", line 3584, in get_updates
    await self._post(
  File "/Users/alexandresimasmaciel/Library/Python/3.9/lib/python/site-packages/telegram/_bot.py", line 613, in _post
    return await self._do_post(
  File "/Users/alexandresimasmaciel/Library/Python/3.9/lib/python/site-packages/telegram/ext/_extbot.py", line 340, in _do_post
    return await super()._do_post(
  File "/Users/alexandresimasmaciel/Library/Python/3.9/lib/python/site-packages/telegram/_bot.py", line 641, in _do_post
    return await request.post(
  File "/Users/alexandresimasmaciel/Library/Python/3.9/lib/python/site-packages/telegram/request/_baserequest.py", line 200, in post
    result = await self._request_wrapper(
  File "/Users/alexandresimasmaciel/Library/Python/3.9/lib/python/site-packages/telegram/request/_baserequest.py", line 381, in _request_wrapper
    raise Conflict(message)
telegram.error.Conflict: Conflict: terminated by other getUpdates request; make sure that only one bot instance is running
2025-03-05 18:59:10 - telegram.ext.Updater - ERROR - Error while getting Updates: Conflict: terminated by other getUpdates request; make sure that only one bot instance is running
2025-03-05 18:59:10 - telegram.ext.Updater - ERROR - Exception happened while polling for updates.
Traceback (most recent call last):
  File "/Users/alexandresimasmaciel/Library/Python/3.9/lib/python/site-packages/telegram/ext/_updater.py", line 688, in _network_loop_retry
    if not await action_cb():
  File "/Users/alexandresimasmaciel/Library/Python/3.9/lib/python/site-packages/telegram/ext/_updater.py", line 384, in polling_action_cb
    raise exc
  File "/Users/alexandresimasmaciel/Library/Python/3.9/lib/python/site-packages/telegram/ext/_updater.py", line 373, in polling_action_cb
    updates = await self.bot.get_updates(
  File "/Users/alexandresimasmaciel/Library/Python/3.9/lib/python/site-packages/telegram/ext/_extbot.py", line 558, in get_updates
    updates = await super().get_updates(
  File "/Users/alexandresimasmaciel/Library/Python/3.9/lib/python/site-packages/telegram/_bot.py", line 525, in decorator
    result = await func(self, *args, **kwargs)  # skipcq: PYL-E1102
  File "/Users/alexandresimasmaciel/Library/Python/3.9/lib/python/site-packages/telegram/_bot.py", line 3584, in get_updates
    await self._post(
  File "/Users/alexandresimasmaciel/Library/Python/3.9/lib/python/site-packages/telegram/_bot.py", line 613, in _post
    return await self._do_post(
  File "/Users/alexandresimasmaciel/Library/Python/3.9/lib/python/site-packages/telegram/ext/_extbot.py", line 340, in _do_post
    return await super()._do_post(
  File "/Users/alexandresimasmaciel/Library/Python/3.9/lib/python/site-packages/telegram/_bot.py", line 641, in _do_post
    return await request.post(
  File "/Users/alexandresimasmaciel/Library/Python/3.9/lib/python/site-packages/telegram/request/_baserequest.py", line 200, in post
    result = await self._request_wrapper(
  File "/Users/alexandresimasmaciel/Library/Python/3.9/lib/python/site-packages/telegram/request/_baserequest.py", line 381, in _request_wrapper
    raise Conflict(message)
telegram.error.Conflict: Conflict: terminated by other getUpdates request; make sure that only one bot instance is running
2025-03-05 18:59:12 - root - ERROR - Sistema de logging inicializado (console: ERROR, arquivo: ERROR)
2025-03-05 18:59:14 - telegram.ext.Updater - ERROR - Error while getting Updates: Conflict: terminated by other getUpdates request; make sure that only one bot instance is running
2025-03-05 18:59:14 - telegram.ext.Updater - ERROR - Exception happened while polling for updates.
Traceback (most recent call last):
  File "/Users/alexandresimasmaciel/Library/Python/3.9/lib/python/site-packages/telegram/ext/_updater.py", line 688, in _network_loop_retry
    if not await action_cb():
  File "/Users/alexandresimasmaciel/Library/Python/3.9/lib/python/site-packages/telegram/ext/_updater.py", line 384, in polling_action_cb
    raise exc
  File "/Users/alexandresimasmaciel/Library/Python/3.9/lib/python/site-packages/telegram/ext/_updater.py", line 373, in polling_action_cb
    updates = await self.bot.get_updates(
  File "/Users/alexandresimasmaciel/Library/Python/3.9/lib/python/site-packages/telegram/ext/_extbot.py", line 558, in get_updates
    updates = await super().get_updates(
  File "/Users/alexandresimasmaciel/Library/Python/3.9/lib/python/site-packages/telegram/_bot.py", line 525, in decorator
    result = await func(self, *args, **kwargs)  # skipcq: PYL-E1102
  File "/Users/alexandresimasmaciel/Library/Python/3.9/lib/python/site-packages/telegram/_bot.py", line 3584, in get_updates
    await self._post(
  File "/Users/alexandresimasmaciel/Library/Python/3.9/lib/python/site-packages/telegram/_bot.py", line 613, in _post
    return await self._do_post(
  File "/Users/alexandresimasmaciel/Library/Python/3.9/lib/python/site-packages/telegram/ext/_extbot.py", line 340, in _do_post
    return await super()._do_post(
  File "/Users/alexandresimasmaciel/Library/Python/3.9/lib/python/site-packages/telegram/_bot.py", line 641, in _do_post
    return await request.post(
  File "/Users/alexandresimasmaciel/Library/Python/3.9/lib/python/site-packages/telegram/request/_baserequest.py", line 200, in post
    result = await self._request_wrapper(
  File "/Users/alexandresimasmaciel/Library/Python/3.9/lib/python/site-packages/telegram/request/_baserequest.py", line 381, in _request_wrapper
    raise Conflict(message)
telegram.error.Conflict: Conflict: terminated by other getUpdates request; make sure that only one bot instance is running
2025-03-05 18:59:19 - telegram.ext.Updater - ERROR - Error while getting Updates: Conflict: terminated by other getUpdates request; make sure that only one bot instance is running
2025-03-05 18:59:19 - telegram.ext.Updater - ERROR - Exception happened while polling for updates.
Traceback (most recent call last):
  File "/Users/alexandresimasmaciel/Library/Python/3.9/lib/python/site-packages/telegram/ext/_updater.py", line 688, in _network_loop_retry
    if not await action_cb():
  File "/Users/alexandresimasmaciel/Library/Python/3.9/lib/python/site-packages/telegram/ext/_updater.py", line 384, in polling_action_cb
    raise exc
  File "/Users/alexandresimasmaciel/Library/Python/3.9/lib/python/site-packages/telegram/ext/_updater.py", line 373, in polling_action_cb
    updates = await self.bot.get_updates(
  File "/Users/alexandresimasmaciel/Library/Python/3.9/lib/python/site-packages/telegram/ext/_extbot.py", line 558, in get_updates
    updates = await super().get_updates(
  File "/Users/alexandresimasmaciel/Library/Python/3.9/lib/python/site-packages/telegram/_bot.py", line 525, in decorator
    result = await func(self, *args, **kwargs)  # skipcq: PYL-E1102
  File "/Users/alexandresimasmaciel/Library/Python/3.9/lib/python/site-packages/telegram/_bot.py", line 3584, in get_updates
    await self._post(
  File "/Users/alexandresimasmaciel/Library/Python/3.9/lib/python/site-packages/telegram/_bot.py", line 613, in _post
    return await self._do_post(
  File "/Users/alexandresimasmaciel/Library/Python/3.9/lib/python/site-packages/telegram/ext/_extbot.py", line 340, in _do_post
    return await super()._do_post(
  File "/Users/alexandresimasmaciel/Library/Python/3.9/lib/python/site-packages/telegram/_bot.py", line 641, in _do_post
    return await request.post(
  File "/Users/alexandresimasmaciel/Library/Python/3.9/lib/python/site-packages/telegram/request/_baserequest.py", line 200, in post
    result = await self._request_wrapper(
  File "/Users/alexandresimasmaciel/Library/Python/3.9/lib/python/site-packages/telegram/request/_baserequest.py", line 381, in _request_wrapper
    raise Conflict(message)
telegram.error.Conflict: Conflict: terminated by other getUpdates request; make sure that only one bot instance is running
2025-03-05 18:59:20 - telegram.ext.Updater - ERROR - Error while getting Updates: Conflict: terminated by other getUpdates request; make sure that only one bot instance is running
2025-03-05 18:59:20 - telegram.ext.Updater - ERROR - Exception happened while polling for updates.
Traceback (most recent call last):
  File "/Users/alexandresimasmaciel/Library/Python/3.9/lib/python/site-packages/telegram/ext/_updater.py", line 688, in _network_loop_retry
    if not await action_cb():
  File "/Users/alexandresimasmaciel/Library/Python/3.9/lib/python/site-packages/telegram/ext/_updater.py", line 384, in polling_action_cb
    raise exc
  File "/Users/alexandresimasmaciel/Library/Python/3.9/lib/python/site-packages/telegram/ext/_updater.py", line 373, in polling_action_cb
    updates = await self.bot.get_updates(
  File "/Users/alexandresimasmaciel/Library/Python/3.9/lib/python/site-packages/telegram/ext/_extbot.py", line 558, in get_updates
    updates = await super().get_updates(
  File "/Users/alexandresimasmaciel/Library/Python/3.9/lib/python/site-packages/telegram/_bot.py", line 525, in decorator
    result = await func(self, *args, **kwargs)  # skipcq: PYL-E1102
  File "/Users/alexandresimasmaciel/Library/Python/3.9/lib/python/site-packages/telegram/_bot.py", line 3584, in get_updates
    await self._post(
  File "/Users/alexandresimasmaciel/Library/Python/3.9/lib/python/site-packages/telegram/_bot.py", line 613, in _post
    return await self._do_post(
  File "/Users/alexandresimasmaciel/Library/Python/3.9/lib/python/site-packages/telegram/ext/_extbot.py", line 340, in _do_post
    return await super()._do_post(
  File "/Users/alexandresimasmaciel/Library/Python/3.9/lib/python/site-packages/telegram/_bot.py", line 641, in _do_post
    return await request.post(
  File "/Users/alexandresimasmaciel/Library/Python/3.9/lib/python/site-packages/telegram/request/_baserequest.py", line 200, in post
    result = await self._request_wrapper(
  File "/Users/alexandresimasmaciel/Library/Python/3.9/lib/python/site-packages/telegram/request/_baserequest.py", line 381, in _request_wrapper
    raise Conflict(message)
telegram.error.Conflict: Conflict: terminated by other getUpdates request; make sure that only one bot instance is running
2025-03-05 18:59:23 - telegram.ext.Updater - ERROR - Error while getting Updates: Conflict: terminated by other getUpdates request; make sure that only one bot instance is running
2025-03-05 18:59:23 - telegram.ext.Updater - ERROR - Exception happened while polling for updates.
Traceback (most recent call last):
  File "/Users/alexandresimasmaciel/Library/Python/3.9/lib/python/site-packages/telegram/ext/_updater.py", line 688, in _network_loop_retry
    if not await action_cb():
  File "/Users/alexandresimasmaciel/Library/Python/3.9/lib/python/site-packages/telegram/ext/_updater.py", line 384, in polling_action_cb
    raise exc
  File "/Users/alexandresimasmaciel/Library/Python/3.9/lib/python/site-packages/telegram/ext/_updater.py", line 373, in polling_action_cb
    updates = await self.bot.get_updates(
  File "/Users/alexandresimasmaciel/Library/Python/3.9/lib/python/site-packages/telegram/ext/_extbot.py", line 558, in get_updates
    updates = await super().get_updates(
  File "/Users/alexandresimasmaciel/Library/Python/3.9/lib/python/site-packages/telegram/_bot.py", line 525, in decorator
    result = await func(self, *args, **kwargs)  # skipcq: PYL-E1102
  File "/Users/alexandresimasmaciel/Library/Python/3.9/lib/python/site-packages/telegram/_bot.py", line 3584, in get_updates
    await self._post(
  File "/Users/alexandresimasmaciel/Library/Python/3.9/lib/python/site-packages/telegram/_bot.py", line 613, in _post
    return await self._do_post(
  File "/Users/alexandresimasmaciel/Library/Python/3.9/lib/python/site-packages/telegram/ext/_extbot.py", line 340, in _do_post
    return await super()._do_post(
  File "/Users/alexandresimasmaciel/Library/Python/3.9/lib/python/site-packages/telegram/_bot.py", line 641, in _do_post
    return await request.post(
  File "/Users/alexandresimasmaciel/Library/Python/3.9/lib/python/site-packages/telegram/request/_baserequest.py", line 200, in post
    result = await self._request_wrapper(
  File "/Users/alexandresimasmaciel/Library/Python/3.9/lib/python/site-packages/telegram/request/_baserequest.py", line 381, in _request_wrapper
    raise Conflict(message)
telegram.error.Conflict: Conflict: terminated by other getUpdates request; make sure that only one bot instance is running
2025-03-05 18:59:29 - telegram.ext.Updater - ERROR - Error while getting Updates: Conflict: terminated by other getUpdates request; make sure that only one bot instance is running
2025-03-05 18:59:29 - telegram.ext.Updater - ERROR - Exception happened while polling for updates.
Traceback (most recent call last):
  File "/Users/alexandresimasmaciel/Library/Python/3.9/lib/python/site-packages/telegram/ext/_updater.py", line 688, in _network_loop_retry
    if not await action_cb():
  File "/Users/alexandresimasmaciel/Library/Python/3.9/lib/python/site-packages/telegram/ext/_updater.py", line 384, in polling_action_cb
    raise exc
  File "/Users/alexandresimasmaciel/Library/Python/3.9/lib/python/site-packages/telegram/ext/_updater.py", line 373, in polling_action_cb
    updates = await self.bot.get_updates(
  File "/Users/alexandresimasmaciel/Library/Python/3.9/lib/python/site-packages/telegram/ext/_extbot.py", line 558, in get_updates
    updates = await super().get_updates(
  File "/Users/alexandresimasmaciel/Library/Python/3.9/lib/python/site-packages/telegram/_bot.py", line 525, in decorator
    result = await func(self, *args, **kwargs)  # skipcq: PYL-E1102
  File "/Users/alexandresimasmaciel/Library/Python/3.9/lib/python/site-packages/telegram/_bot.py", line 3584, in get_updates
    await self._post(
  File "/Users/alexandresimasmaciel/Library/Python/3.9/lib/python/site-packages/telegram/_bot.py", line 613, in _post
    return await self._do_post(
  File "/Users/alexandresimasmaciel/Library/Python/3.9/lib/python/site-packages/telegram/ext/_extbot.py", line 340, in _do_post
    return await super()._do_post(
  File "/Users/alexandresimasmaciel/Library/Python/3.9/lib/python/site-packages/telegram/_bot.py", line 641, in _do_post
    return await request.post(
  File "/Users/alexandresimasmaciel/Library/Python/3.9/lib/python/site-packages/telegram/request/_baserequest.py", line 200, in post
    result = await self._request_wrapper(
  File "/Users/alexandresimasmaciel/Library/Python/3.9/lib/python/site-packages/telegram/request/_baserequest.py", line 381, in _request_wrapper
    raise Conflict(message)
telegram.error.Conflict: Conflict: terminated by other getUpdates request; make sure that only one bot instance is running
2025-03-05 18:59:32 - telegram.ext.Updater - ERROR - Error while getting Updates: Conflict: terminated by other getUpdates request; make sure that only one bot instance is running
2025-03-05 18:59:32 - telegram.ext.Updater - ERROR - Exception happened while polling for updates.
Traceback (most recent call last):
  File "/Users/alexandresimasmaciel/Library/Python/3.9/lib/python/site-packages/telegram/ext/_updater.py", line 688, in _network_loop_retry
    if not await action_cb():
  File "/Users/alexandresimasmaciel/Library/Python/3.9/lib/python/site-packages/telegram/ext/_updater.py", line 384, in polling_action_cb
    raise exc
  File "/Users/alexandresimasmaciel/Library/Python/3.9/lib/python/site-packages/telegram/ext/_updater.py", line 373, in polling_action_cb
    updates = await self.bot.get_updates(
  File "/Users/alexandresimasmaciel/Library/Python/3.9/lib/python/site-packages/telegram/ext/_extbot.py", line 558, in get_updates
    updates = await super().get_updates(
  File "/Users/alexandresimasmaciel/Library/Python/3.9/lib/python/site-packages/telegram/_bot.py", line 525, in decorator
    result = await func(self, *args, **kwargs)  # skipcq: PYL-E1102
  File "/Users/alexandresimasmaciel/Library/Python/3.9/lib/python/site-packages/telegram/_bot.py", line 3584, in get_updates
    await self._post(
  File "/Users/alexandresimasmaciel/Library/Python/3.9/lib/python/site-packages/telegram/_bot.py", line 613, in _post
    return await self._do_post(
  File "/Users/alexandresimasmaciel/Library/Python/3.9/lib/python/site-packages/telegram/ext/_extbot.py", line 340, in _do_post
    return await super()._do_post(
  File "/Users/alexandresimasmaciel/Library/Python/3.9/lib/python/site-packages/telegram/_bot.py", line 641, in _do_post
    return await request.post(
  File "/Users/alexandresimasmaciel/Library/Python/3.9/lib/python/site-packages/telegram/request/_baserequest.py", line 200, in post
    result = await self._request_wrapper(
  File "/Users/alexandresimasmaciel/Library/Python/3.9/lib/python/site-packages/telegram/request/_baserequest.py", line 381, in _request_wrapper
    raise Conflict(message)
telegram.error.Conflict: Conflict: terminated by other getUpdates request; make sure that only one bot instance is running
2025-03-05 18:59:33 - telegram.ext.Updater - ERROR - Error while getting Updates: Conflict: terminated by other getUpdates request; make sure that only one bot instance is running
2025-03-05 18:59:33 - telegram.ext.Updater - ERROR - Exception happened while polling for updates.
Traceback (most recent call last):
  File "/Users/alexandresimasmaciel/Library/Python/3.9/lib/python/site-packages/telegram/ext/_updater.py", line 688, in _network_loop_retry
    if not await action_cb():
  File "/Users/alexandresimasmaciel/Library/Python/3.9/lib/python/site-packages/telegram/ext/_updater.py", line 384, in polling_action_cb
    raise exc
  File "/Users/alexandresimasmaciel/Library/Python/3.9/lib/python/site-packages/telegram/ext/_updater.py", line 373, in polling_action_cb
    updates = await self.bot.get_updates(
  File "/Users/alexandresimasmaciel/Library/Python/3.9/lib/python/site-packages/telegram/ext/_extbot.py", line 558, in get_updates
    updates = await super().get_updates(
  File "/Users/alexandresimasmaciel/Library/Python/3.9/lib/python/site-packages/telegram/_bot.py", line 525, in decorator
    result = await func(self, *args, **kwargs)  # skipcq: PYL-E1102
  File "/Users/alexandresimasmaciel/Library/Python/3.9/lib/python/site-packages/telegram/_bot.py", line 3584, in get_updates
    await self._post(
  File "/Users/alexandresimasmaciel/Library/Python/3.9/lib/python/site-packages/telegram/_bot.py", line 613, in _post
    return await self._do_post(
  File "/Users/alexandresimasmaciel/Library/Python/3.9/lib/python/site-packages/telegram/ext/_extbot.py", line 340, in _do_post
    return await super()._do_post(
  File "/Users/alexandresimasmaciel/Library/Python/3.9/lib/python/site-packages/telegram/_bot.py", line 641, in _do_post
    return await request.post(
  File "/Users/alexandresimasmaciel/Library/Python/3.9/lib/python/site-packages/telegram/request/_baserequest.py", line 200, in post
    result = await self._request_wrapper(
  File "/Users/alexandresimasmaciel/Library/Python/3.9/lib/python/site-packages/telegram/request/_baserequest.py", line 381, in _request_wrapper
    raise Conflict(message)
telegram.error.Conflict: Conflict: terminated by other getUpdates request; make sure that only one bot instance is running
2025-03-05 18:59:37 - telegram.ext.Updater - ERROR - Error while getting Updates: Conflict: terminated by other getUpdates request; make sure that only one bot instance is running
2025-03-05 18:59:37 - telegram.ext.Updater - ERROR - Exception happened while polling for updates.
Traceback (most recent call last):
  File "/Users/alexandresimasmaciel/Library/Python/3.9/lib/python/site-packages/telegram/ext/_updater.py", line 688, in _network_loop_retry
    if not await action_cb():
  File "/Users/alexandresimasmaciel/Library/Python/3.9/lib/python/site-packages/telegram/ext/_updater.py", line 384, in polling_action_cb
    raise exc
  File "/Users/alexandresimasmaciel/Library/Python/3.9/lib/python/site-packages/telegram/ext/_updater.py", line 373, in polling_action_cb
    updates = await self.bot.get_updates(
  File "/Users/alexandresimasmaciel/Library/Python/3.9/lib/python/site-packages/telegram/ext/_extbot.py", line 558, in get_updates
    updates = await super().get_updates(
  File "/Users/alexandresimasmaciel/Library/Python/3.9/lib/python/site-packages/telegram/_bot.py", line 525, in decorator
    result = await func(self, *args, **kwargs)  # skipcq: PYL-E1102
  File "/Users/alexandresimasmaciel/Library/Python/3.9/lib/python/site-packages/telegram/_bot.py", line 3584, in get_updates
    await self._post(
  File "/Users/alexandresimasmaciel/Library/Python/3.9/lib/python/site-packages/telegram/_bot.py", line 613, in _post
    return await self._do_post(
  File "/Users/alexandresimasmaciel/Library/Python/3.9/lib/python/site-packages/telegram/ext/_extbot.py", line 340, in _do_post
    return await super()._do_post(
  File "/Users/alexandresimasmaciel/Library/Python/3.9/lib/python/site-packages/telegram/_bot.py", line 641, in _do_post
    return await request.post(
  File "/Users/alexandresimasmaciel/Library/Python/3.9/lib/python/site-packages/telegram/request/_baserequest.py", line 200, in post
    result = await self._request_wrapper(
  File "/Users/alexandresimasmaciel/Library/Python/3.9/lib/python/site-packages/telegram/request/_baserequest.py", line 381, in _request_wrapper
    raise Conflict(message)
telegram.error.Conflict: Conflict: terminated by other getUpdates request; make sure that only one bot instance is running
2025-03-05 18:59:46 - telegram.ext.Updater - ERROR - Error while getting Updates: Conflict: terminated by other getUpdates request; make sure that only one bot instance is running
2025-03-05 18:59:46 - telegram.ext.Updater - ERROR - Exception happened while polling for updates.
Traceback (most recent call last):
  File "/Users/alexandresimasmaciel/Library/Python/3.9/lib/python/site-packages/telegram/ext/_updater.py", line 688, in _network_loop_retry
    if not await action_cb():
  File "/Users/alexandresimasmaciel/Library/Python/3.9/lib/python/site-packages/telegram/ext/_updater.py", line 384, in polling_action_cb
    raise exc
  File "/Users/alexandresimasmaciel/Library/Python/3.9/lib/python/site-packages/telegram/ext/_updater.py", line 373, in polling_action_cb
    updates = await self.bot.get_updates(
  File "/Users/alexandresimasmaciel/Library/Python/3.9/lib/python/site-packages/telegram/ext/_extbot.py", line 558, in get_updates
    updates = await super().get_updates(
  File "/Users/alexandresimasmaciel/Library/Python/3.9/lib/python/site-packages/telegram/_bot.py", line 525, in decorator
    result = await func(self, *args, **kwargs)  # skipcq: PYL-E1102
  File "/Users/alexandresimasmaciel/Library/Python/3.9/lib/python/site-packages/telegram/_bot.py", line 3584, in get_updates
    await self._post(
  File "/Users/alexandresimasmaciel/Library/Python/3.9/lib/python/site-packages/telegram/_bot.py", line 613, in _post
    return await self._do_post(
  File "/Users/alexandresimasmaciel/Library/Python/3.9/lib/python/site-packages/telegram/ext/_extbot.py", line 340, in _do_post
    return await super()._do_post(
  File "/Users/alexandresimasmaciel/Library/Python/3.9/lib/python/site-packages/telegram/_bot.py", line 641, in _do_post
    return await request.post(
  File "/Users/alexandresimasmaciel/Library/Python/3.9/lib/python/site-packages/telegram/request/_baserequest.py", line 200, in post
    result = await self._request_wrapper(
  File "/Users/alexandresimasmaciel/Library/Python/3.9/lib/python/site-packages/telegram/request/_baserequest.py", line 381, in _request_wrapper
    raise Conflict(message)
telegram.error.Conflict: Conflict: terminated by other getUpdates request; make sure that only one bot instance is running
2025-03-05 18:59:50 - telegram.ext.Updater - ERROR - Error while getting Updates: Conflict: terminated by other getUpdates request; make sure that only one bot instance is running
2025-03-05 18:59:50 - telegram.ext.Updater - ERROR - Exception happened while polling for updates.
Traceback (most recent call last):
  File "/Users/alexandresimasmaciel/Library/Python/3.9/lib/python/site-packages/telegram/ext/_updater.py", line 688, in _network_loop_retry
    if not await action_cb():
  File "/Users/alexandresimasmaciel/Library/Python/3.9/lib/python/site-packages/telegram/ext/_updater.py", line 384, in polling_action_cb
    raise exc
  File "/Users/alexandresimasmaciel/Library/Python/3.9/lib/python/site-packages/telegram/ext/_updater.py", line 373, in polling_action_cb
    updates = await self.bot.get_updates(
  File "/Users/alexandresimasmaciel/Library/Python/3.9/lib/python/site-packages/telegram/ext/_extbot.py", line 558, in get_updates
    updates = await super().get_updates(
  File "/Users/alexandresimasmaciel/Library/Python/3.9/lib/python/site-packages/telegram/_bot.py", line 525, in decorator
    result = await func(self, *args, **kwargs)  # skipcq: PYL-E1102
  File "/Users/alexandresimasmaciel/Library/Python/3.9/lib/python/site-packages/telegram/_bot.py", line 3584, in get_updates
    await self._post(
  File "/Users/alexandresimasmaciel/Library/Python/3.9/lib/python/site-packages/telegram/_bot.py", line 613, in _post
    return await self._do_post(
  File "/Users/alexandresimasmaciel/Library/Python/3.9/lib/python/site-packages/telegram/ext/_extbot.py", line 340, in _do_post
    return await super()._do_post(
  File "/Users/alexandresimasmaciel/Library/Python/3.9/lib/python/site-packages/telegram/_bot.py", line 641, in _do_post
    return await request.post(
  File "/Users/alexandresimasmaciel/Library/Python/3.9/lib/python/site-packages/telegram/request/_baserequest.py", line 200, in post
    result = await self._request_wrapper(
  File "/Users/alexandresimasmaciel/Library/Python/3.9/lib/python/site-packages/telegram/request/_baserequest.py", line 381, in _request_wrapper
    raise Conflict(message)
telegram.error.Conflict: Conflict: terminated by other getUpdates request; make sure that only one bot instance is running
2025-03-05 18:59:50 - telegram.ext.Updater - ERROR - Error while getting Updates: Conflict: terminated by other getUpdates request; make sure that only one bot instance is running
2025-03-05 18:59:50 - telegram.ext.Updater - ERROR - Exception happened while polling for updates.
Traceback (most recent call last):
  File "/Users/alexandresimasmaciel/Library/Python/3.9/lib/python/site-packages/telegram/ext/_updater.py", line 688, in _network_loop_retry
    if not await action_cb():
  File "/Users/alexandresimasmaciel/Library/Python/3.9/lib/python/site-packages/telegram/ext/_updater.py", line 384, in polling_action_cb
    raise exc
  File "/Users/alexandresimasmaciel/Library/Python/3.9/lib/python/site-packages/telegram/ext/_updater.py", line 373, in polling_action_cb
    updates = await self.bot.get_updates(
  File "/Users/alexandresimasmaciel/Library/Python/3.9/lib/python/site-packages/telegram/ext/_extbot.py", line 558, in get_updates
    updates = await super().get_updates(
  File "/Users/alexandresimasmaciel/Library/Python/3.9/lib/python/site-packages/telegram/_bot.py", line 525, in decorator
    result = await func(self, *args, **kwargs)  # skipcq: PYL-E1102
  File "/Users/alexandresimasmaciel/Library/Python/3.9/lib/python/site-packages/telegram/_bot.py", line 3584, in get_updates
    await self._post(
  File "/Users/alexandresimasmaciel/Library/Python/3.9/lib/python/site-packages/telegram/_bot.py", line 613, in _post
    return await self._do_post(
  File "/Users/alexandresimasmaciel/Library/Python/3.9/lib/python/site-packages/telegram/ext/_extbot.py", line 340, in _do_post
    return await super()._do_post(
  File "/Users/alexandresimasmaciel/Library/Python/3.9/lib/python/site-packages/telegram/_bot.py", line 641, in _do_post
    return await request.post(
  File "/Users/alexandresimasmaciel/Library/Python/3.9/lib/python/site-packages/telegram/request/_baserequest.py", line 200, in post
    result = await self._request_wrapper(
  File "/Users/alexandresimasmaciel/Library/Python/3.9/lib/python/site-packages/telegram/request/_baserequest.py", line 381, in _request_wrapper
    raise Conflict(message)
telegram.error.Conflict: Conflict: terminated by other getUpdates request; make sure that only one bot instance is running
2025-03-05 18:59:51 - root - ERROR - Sistema de logging inicializado (console: ERROR, arquivo: ERROR)
2025-03-05 18:59:53 - telegram.ext.Updater - ERROR - Error while getting Updates: Conflict: terminated by other getUpdates request; make sure that only one bot instance is running
2025-03-05 18:59:53 - telegram.ext.Updater - ERROR - Exception happened while polling for updates.
Traceback (most recent call last):
  File "/Users/alexandresimasmaciel/Library/Python/3.9/lib/python/site-packages/telegram/ext/_updater.py", line 688, in _network_loop_retry
    if not await action_cb():
  File "/Users/alexandresimasmaciel/Library/Python/3.9/lib/python/site-packages/telegram/ext/_updater.py", line 384, in polling_action_cb
    raise exc
  File "/Users/alexandresimasmaciel/Library/Python/3.9/lib/python/site-packages/telegram/ext/_updater.py", line 373, in polling_action_cb
    updates = await self.bot.get_updates(
  File "/Users/alexandresimasmaciel/Library/Python/3.9/lib/python/site-packages/telegram/ext/_extbot.py", line 558, in get_updates
    updates = await super().get_updates(
  File "/Users/alexandresimasmaciel/Library/Python/3.9/lib/python/site-packages/telegram/_bot.py", line 525, in decorator
    result = await func(self, *args, **kwargs)  # skipcq: PYL-E1102
  File "/Users/alexandresimasmaciel/Library/Python/3.9/lib/python/site-packages/telegram/_bot.py", line 3584, in get_updates
    await self._post(
  File "/Users/alexandresimasmaciel/Library/Python/3.9/lib/python/site-packages/telegram/_bot.py", line 613, in _post
    return await self._do_post(
  File "/Users/alexandresimasmaciel/Library/Python/3.9/lib/python/site-packages/telegram/ext/_extbot.py", line 340, in _do_post
    return await super()._do_post(
  File "/Users/alexandresimasmaciel/Library/Python/3.9/lib/python/site-packages/telegram/_bot.py", line 641, in _do_post
    return await request.post(
  File "/Users/alexandresimasmaciel/Library/Python/3.9/lib/python/site-packages/telegram/request/_baserequest.py", line 200, in post
    result = await self._request_wrapper(
  File "/Users/alexandresimasmaciel/Library/Python/3.9/lib/python/site-packages/telegram/request/_baserequest.py", line 381, in _request_wrapper
    raise Conflict(message)
telegram.error.Conflict: Conflict: terminated by other getUpdates request; make sure that only one bot instance is running
2025-03-05 18:59:54 - telegram.ext.Updater - ERROR - Error while getting Updates: Conflict: terminated by other getUpdates request; make sure that only one bot instance is running
2025-03-05 18:59:54 - telegram.ext.Updater - ERROR - Exception happened while polling for updates.
Traceback (most recent call last):
  File "/Users/alexandresimasmaciel/Library/Python/3.9/lib/python/site-packages/telegram/ext/_updater.py", line 688, in _network_loop_retry
    if not await action_cb():
  File "/Users/alexandresimasmaciel/Library/Python/3.9/lib/python/site-packages/telegram/ext/_updater.py", line 384, in polling_action_cb
    raise exc
  File "/Users/alexandresimasmaciel/Library/Python/3.9/lib/python/site-packages/telegram/ext/_updater.py", line 373, in polling_action_cb
    updates = await self.bot.get_updates(
  File "/Users/alexandresimasmaciel/Library/Python/3.9/lib/python/site-packages/telegram/ext/_extbot.py", line 558, in get_updates
    updates = await super().get_updates(
  File "/Users/alexandresimasmaciel/Library/Python/3.9/lib/python/site-packages/telegram/_bot.py", line 525, in decorator
    result = await func(self, *args, **kwargs)  # skipcq: PYL-E1102
  File "/Users/alexandresimasmaciel/Library/Python/3.9/lib/python/site-packages/telegram/_bot.py", line 3584, in get_updates
    await self._post(
  File "/Users/alexandresimasmaciel/Library/Python/3.9/lib/python/site-packages/telegram/_bot.py", line 613, in _post
    return await self._do_post(
  File "/Users/alexandresimasmaciel/Library/Python/3.9/lib/python/site-packages/telegram/ext/_extbot.py", line 340, in _do_post
    return await super()._do_post(
  File "/Users/alexandresimasmaciel/Library/Python/3.9/lib/python/site-packages/telegram/_bot.py", line 641, in _do_post
    return await request.post(
  File "/Users/alexandresimasmaciel/Library/Python/3.9/lib/python/site-packages/telegram/request/_baserequest.py", line 200, in post
    result = await self._request_wrapper(
  File "/Users/alexandresimasmaciel/Library/Python/3.9/lib/python/site-packages/telegram/request/_baserequest.py", line 381, in _request_wrapper
    raise Conflict(message)
telegram.error.Conflict: Conflict: terminated by other getUpdates request; make sure that only one bot instance is running
2025-03-05 18:59:59 - telegram.ext.Updater - ERROR - Error while getting Updates: Conflict: terminated by other getUpdates request; make sure that only one bot instance is running
2025-03-05 18:59:59 - telegram.ext.Updater - ERROR - Exception happened while polling for updates.
Traceback (most recent call last):
  File "/Users/alexandresimasmaciel/Library/Python/3.9/lib/python/site-packages/telegram/ext/_updater.py", line 688, in _network_loop_retry
    if not await action_cb():
  File "/Users/alexandresimasmaciel/Library/Python/3.9/lib/python/site-packages/telegram/ext/_updater.py", line 384, in polling_action_cb
    raise exc
  File "/Users/alexandresimasmaciel/Library/Python/3.9/lib/python/site-packages/telegram/ext/_updater.py", line 373, in polling_action_cb
    updates = await self.bot.get_updates(
  File "/Users/alexandresimasmaciel/Library/Python/3.9/lib/python/site-packages/telegram/ext/_extbot.py", line 558, in get_updates
    updates = await super().get_updates(
  File "/Users/alexandresimasmaciel/Library/Python/3.9/lib/python/site-packages/telegram/_bot.py", line 525, in decorator
    result = await func(self, *args, **kwargs)  # skipcq: PYL-E1102
  File "/Users/alexandresimasmaciel/Library/Python/3.9/lib/python/site-packages/telegram/_bot.py", line 3584, in get_updates
    await self._post(
  File "/Users/alexandresimasmaciel/Library/Python/3.9/lib/python/site-packages/telegram/_bot.py", line 613, in _post
    return await self._do_post(
  File "/Users/alexandresimasmaciel/Library/Python/3.9/lib/python/site-packages/telegram/ext/_extbot.py", line 340, in _do_post
    return await super()._do_post(
  File "/Users/alexandresimasmaciel/Library/Python/3.9/lib/python/site-packages/telegram/_bot.py", line 641, in _do_post
    return await request.post(
  File "/Users/alexandresimasmaciel/Library/Python/3.9/lib/python/site-packages/telegram/request/_baserequest.py", line 200, in post
    result = await self._request_wrapper(
  File "/Users/alexandresimasmaciel/Library/Python/3.9/lib/python/site-packages/telegram/request/_baserequest.py", line 381, in _request_wrapper
    raise Conflict(message)
telegram.error.Conflict: Conflict: terminated by other getUpdates request; make sure that only one bot instance is running
2025-03-05 19:00:00 - telegram.ext.Updater - ERROR - Error while getting Updates: Conflict: terminated by other getUpdates request; make sure that only one bot instance is running
2025-03-05 19:00:00 - telegram.ext.Updater - ERROR - Exception happened while polling for updates.
Traceback (most recent call last):
  File "/Users/alexandresimasmaciel/Library/Python/3.9/lib/python/site-packages/telegram/ext/_updater.py", line 688, in _network_loop_retry
    if not await action_cb():
  File "/Users/alexandresimasmaciel/Library/Python/3.9/lib/python/site-packages/telegram/ext/_updater.py", line 384, in polling_action_cb
    raise exc
  File "/Users/alexandresimasmaciel/Library/Python/3.9/lib/python/site-packages/telegram/ext/_updater.py", line 373, in polling_action_cb
    updates = await self.bot.get_updates(
  File "/Users/alexandresimasmaciel/Library/Python/3.9/lib/python/site-packages/telegram/ext/_extbot.py", line 558, in get_updates
    updates = await super().get_updates(
  File "/Users/alexandresimasmaciel/Library/Python/3.9/lib/python/site-packages/telegram/_bot.py", line 525, in decorator
    result = await func(self, *args, **kwargs)  # skipcq: PYL-E1102
  File "/Users/alexandresimasmaciel/Library/Python/3.9/lib/python/site-packages/telegram/_bot.py", line 3584, in get_updates
    await self._post(
  File "/Users/alexandresimasmaciel/Library/Python/3.9/lib/python/site-packages/telegram/_bot.py", line 613, in _post
    return await self._do_post(
  File "/Users/alexandresimasmaciel/Library/Python/3.9/lib/python/site-packages/telegram/ext/_extbot.py", line 340, in _do_post
    return await super()._do_post(
  File "/Users/alexandresimasmaciel/Library/Python/3.9/lib/python/site-packages/telegram/_bot.py", line 641, in _do_post
    return await request.post(
  File "/Users/alexandresimasmaciel/Library/Python/3.9/lib/python/site-packages/telegram/request/_baserequest.py", line 200, in post
    result = await self._request_wrapper(
  File "/Users/alexandresimasmaciel/Library/Python/3.9/lib/python/site-packages/telegram/request/_baserequest.py", line 381, in _request_wrapper
    raise Conflict(message)
telegram.error.Conflict: Conflict: terminated by other getUpdates request; make sure that only one bot instance is running
2025-03-05 19:00:04 - telegram.ext.Updater - ERROR - Error while getting Updates: Conflict: terminated by other getUpdates request; make sure that only one bot instance is running
2025-03-05 19:00:04 - telegram.ext.Updater - ERROR - Exception happened while polling for updates.
Traceback (most recent call last):
  File "/Users/alexandresimasmaciel/Library/Python/3.9/lib/python/site-packages/telegram/ext/_updater.py", line 688, in _network_loop_retry
    if not await action_cb():
  File "/Users/alexandresimasmaciel/Library/Python/3.9/lib/python/site-packages/telegram/ext/_updater.py", line 384, in polling_action_cb
    raise exc
  File "/Users/alexandresimasmaciel/Library/Python/3.9/lib/python/site-packages/telegram/ext/_updater.py", line 373, in polling_action_cb
    updates = await self.bot.get_updates(
  File "/Users/alexandresimasmaciel/Library/Python/3.9/lib/python/site-packages/telegram/ext/_extbot.py", line 558, in get_updates
    updates = await super().get_updates(
  File "/Users/alexandresimasmaciel/Library/Python/3.9/lib/python/site-packages/telegram/_bot.py", line 525, in decorator
    result = await func(self, *args, **kwargs)  # skipcq: PYL-E1102
  File "/Users/alexandresimasmaciel/Library/Python/3.9/lib/python/site-packages/telegram/_bot.py", line 3584, in get_updates
    await self._post(
  File "/Users/alexandresimasmaciel/Library/Python/3.9/lib/python/site-packages/telegram/_bot.py", line 613, in _post
    return await self._do_post(
  File "/Users/alexandresimasmaciel/Library/Python/3.9/lib/python/site-packages/telegram/ext/_extbot.py", line 340, in _do_post
    return await super()._do_post(
  File "/Users/alexandresimasmaciel/Library/Python/3.9/lib/python/site-packages/telegram/_bot.py", line 641, in _do_post
    return await request.post(
  File "/Users/alexandresimasmaciel/Library/Python/3.9/lib/python/site-packages/telegram/request/_baserequest.py", line 200, in post
    result = await self._request_wrapper(
  File "/Users/alexandresimasmaciel/Library/Python/3.9/lib/python/site-packages/telegram/request/_baserequest.py", line 381, in _request_wrapper
    raise Conflict(message)
telegram.error.Conflict: Conflict: terminated by other getUpdates request; make sure that only one bot instance is running
2025-03-05 19:00:08 - telegram.ext.Updater - ERROR - Error while getting Updates: Conflict: terminated by other getUpdates request; make sure that only one bot instance is running
2025-03-05 19:00:08 - telegram.ext.Updater - ERROR - Exception happened while polling for updates.
Traceback (most recent call last):
  File "/Users/alexandresimasmaciel/Library/Python/3.9/lib/python/site-packages/telegram/ext/_updater.py", line 688, in _network_loop_retry
    if not await action_cb():
  File "/Users/alexandresimasmaciel/Library/Python/3.9/lib/python/site-packages/telegram/ext/_updater.py", line 384, in polling_action_cb
    raise exc
  File "/Users/alexandresimasmaciel/Library/Python/3.9/lib/python/site-packages/telegram/ext/_updater.py", line 373, in polling_action_cb
    updates = await self.bot.get_updates(
  File "/Users/alexandresimasmaciel/Library/Python/3.9/lib/python/site-packages/telegram/ext/_extbot.py", line 558, in get_updates
    updates = await super().get_updates(
  File "/Users/alexandresimasmaciel/Library/Python/3.9/lib/python/site-packages/telegram/_bot.py", line 525, in decorator
    result = await func(self, *args, **kwargs)  # skipcq: PYL-E1102
  File "/Users/alexandresimasmaciel/Library/Python/3.9/lib/python/site-packages/telegram/_bot.py", line 3584, in get_updates
    await self._post(
  File "/Users/alexandresimasmaciel/Library/Python/3.9/lib/python/site-packages/telegram/_bot.py", line 613, in _post
    return await self._do_post(
  File "/Users/alexandresimasmaciel/Library/Python/3.9/lib/python/site-packages/telegram/ext/_extbot.py", line 340, in _do_post
    return await super()._do_post(
  File "/Users/alexandresimasmaciel/Library/Python/3.9/lib/python/site-packages/telegram/_bot.py", line 641, in _do_post
    return await request.post(
  File "/Users/alexandresimasmaciel/Library/Python/3.9/lib/python/site-packages/telegram/request/_baserequest.py", line 200, in post
    result = await self._request_wrapper(
  File "/Users/alexandresimasmaciel/Library/Python/3.9/lib/python/site-packages/telegram/request/_baserequest.py", line 381, in _request_wrapper
    raise Conflict(message)
telegram.error.Conflict: Conflict: terminated by other getUpdates request; make sure that only one bot instance is running
2025-03-05 19:00:08 - telegram.ext.Updater - ERROR - Error while getting Updates: Conflict: terminated by other getUpdates request; make sure that only one bot instance is running
2025-03-05 19:00:08 - telegram.ext.Updater - ERROR - Exception happened while polling for updates.
Traceback (most recent call last):
  File "/Users/alexandresimasmaciel/Library/Python/3.9/lib/python/site-packages/telegram/ext/_updater.py", line 688, in _network_loop_retry
    if not await action_cb():
  File "/Users/alexandresimasmaciel/Library/Python/3.9/lib/python/site-packages/telegram/ext/_updater.py", line 384, in polling_action_cb
    raise exc
  File "/Users/alexandresimasmaciel/Library/Python/3.9/lib/python/site-packages/telegram/ext/_updater.py", line 373, in polling_action_cb
    updates = await self.bot.get_updates(
  File "/Users/alexandresimasmaciel/Library/Python/3.9/lib/python/site-packages/telegram/ext/_extbot.py", line 558, in get_updates
    updates = await super().get_updates(
  File "/Users/alexandresimasmaciel/Library/Python/3.9/lib/python/site-packages/telegram/_bot.py", line 525, in decorator
    result = await func(self, *args, **kwargs)  # skipcq: PYL-E1102
  File "/Users/alexandresimasmaciel/Library/Python/3.9/lib/python/site-packages/telegram/_bot.py", line 3584, in get_updates
    await self._post(
  File "/Users/alexandresimasmaciel/Library/Python/3.9/lib/python/site-packages/telegram/_bot.py", line 613, in _post
    return await self._do_post(
  File "/Users/alexandresimasmaciel/Library/Python/3.9/lib/python/site-packages/telegram/ext/_extbot.py", line 340, in _do_post
    return await super()._do_post(
  File "/Users/alexandresimasmaciel/Library/Python/3.9/lib/python/site-packages/telegram/_bot.py", line 641, in _do_post
    return await request.post(
  File "/Users/alexandresimasmaciel/Library/Python/3.9/lib/python/site-packages/telegram/request/_baserequest.py", line 200, in post
    result = await self._request_wrapper(
  File "/Users/alexandresimasmaciel/Library/Python/3.9/lib/python/site-packages/telegram/request/_baserequest.py", line 381, in _request_wrapper
    raise Conflict(message)
telegram.error.Conflict: Conflict: terminated by other getUpdates request; make sure that only one bot instance is running
2025-03-05 19:00:12 - telegram.ext.Updater - ERROR - Error while getting Updates: Conflict: terminated by other getUpdates request; make sure that only one bot instance is running
2025-03-05 19:00:12 - telegram.ext.Updater - ERROR - Exception happened while polling for updates.
Traceback (most recent call last):
  File "/Users/alexandresimasmaciel/Library/Python/3.9/lib/python/site-packages/telegram/ext/_updater.py", line 688, in _network_loop_retry
    if not await action_cb():
  File "/Users/alexandresimasmaciel/Library/Python/3.9/lib/python/site-packages/telegram/ext/_updater.py", line 384, in polling_action_cb
    raise exc
  File "/Users/alexandresimasmaciel/Library/Python/3.9/lib/python/site-packages/telegram/ext/_updater.py", line 373, in polling_action_cb
    updates = await self.bot.get_updates(
  File "/Users/alexandresimasmaciel/Library/Python/3.9/lib/python/site-packages/telegram/ext/_extbot.py", line 558, in get_updates
    updates = await super().get_updates(
  File "/Users/alexandresimasmaciel/Library/Python/3.9/lib/python/site-packages/telegram/_bot.py", line 525, in decorator
    result = await func(self, *args, **kwargs)  # skipcq: PYL-E1102
  File "/Users/alexandresimasmaciel/Library/Python/3.9/lib/python/site-packages/telegram/_bot.py", line 3584, in get_updates
    await self._post(
  File "/Users/alexandresimasmaciel/Library/Python/3.9/lib/python/site-packages/telegram/_bot.py", line 613, in _post
    return await self._do_post(
  File "/Users/alexandresimasmaciel/Library/Python/3.9/lib/python/site-packages/telegram/ext/_extbot.py", line 340, in _do_post
    return await super()._do_post(
  File "/Users/alexandresimasmaciel/Library/Python/3.9/lib/python/site-packages/telegram/_bot.py", line 641, in _do_post
    return await request.post(
  File "/Users/alexandresimasmaciel/Library/Python/3.9/lib/python/site-packages/telegram/request/_baserequest.py", line 200, in post
    result = await self._request_wrapper(
  File "/Users/alexandresimasmaciel/Library/Python/3.9/lib/python/site-packages/telegram/request/_baserequest.py", line 381, in _request_wrapper
    raise Conflict(message)
telegram.error.Conflict: Conflict: terminated by other getUpdates request; make sure that only one bot instance is running
2025-03-05 19:00:13 - telegram.ext.Updater - ERROR - Error while getting Updates: Conflict: terminated by other getUpdates request; make sure that only one bot instance is running
2025-03-05 19:00:13 - telegram.ext.Updater - ERROR - Exception happened while polling for updates.
Traceback (most recent call last):
  File "/Users/alexandresimasmaciel/Library/Python/3.9/lib/python/site-packages/telegram/ext/_updater.py", line 688, in _network_loop_retry
    if not await action_cb():
  File "/Users/alexandresimasmaciel/Library/Python/3.9/lib/python/site-packages/telegram/ext/_updater.py", line 384, in polling_action_cb
    raise exc
  File "/Users/alexandresimasmaciel/Library/Python/3.9/lib/python/site-packages/telegram/ext/_updater.py", line 373, in polling_action_cb
    updates = await self.bot.get_updates(
  File "/Users/alexandresimasmaciel/Library/Python/3.9/lib/python/site-packages/telegram/ext/_extbot.py", line 558, in get_updates
    updates = await super().get_updates(
  File "/Users/alexandresimasmaciel/Library/Python/3.9/lib/python/site-packages/telegram/_bot.py", line 525, in decorator
    result = await func(self, *args, **kwargs)  # skipcq: PYL-E1102
  File "/Users/alexandresimasmaciel/Library/Python/3.9/lib/python/site-packages/telegram/_bot.py", line 3584, in get_updates
    await self._post(
  File "/Users/alexandresimasmaciel/Library/Python/3.9/lib/python/site-packages/telegram/_bot.py", line 613, in _post
    return await self._do_post(
  File "/Users/alexandresimasmaciel/Library/Python/3.9/lib/python/site-packages/telegram/ext/_extbot.py", line 340, in _do_post
    return await super()._do_post(
  File "/Users/alexandresimasmaciel/Library/Python/3.9/lib/python/site-packages/telegram/_bot.py", line 641, in _do_post
    return await request.post(
  File "/Users/alexandresimasmaciel/Library/Python/3.9/lib/python/site-packages/telegram/request/_baserequest.py", line 200, in post
    result = await self._request_wrapper(
  File "/Users/alexandresimasmaciel/Library/Python/3.9/lib/python/site-packages/telegram/request/_baserequest.py", line 381, in _request_wrapper
    raise Conflict(message)
telegram.error.Conflict: Conflict: terminated by other getUpdates request; make sure that only one bot instance is running
2025-03-05 19:00:16 - telegram.ext.Updater - ERROR - Error while getting Updates: Conflict: terminated by other getUpdates request; make sure that only one bot instance is running
2025-03-05 19:00:16 - telegram.ext.Updater - ERROR - Exception happened while polling for updates.
Traceback (most recent call last):
  File "/Users/alexandresimasmaciel/Library/Python/3.9/lib/python/site-packages/telegram/ext/_updater.py", line 688, in _network_loop_retry
    if not await action_cb():
  File "/Users/alexandresimasmaciel/Library/Python/3.9/lib/python/site-packages/telegram/ext/_updater.py", line 384, in polling_action_cb
    raise exc
  File "/Users/alexandresimasmaciel/Library/Python/3.9/lib/python/site-packages/telegram/ext/_updater.py", line 373, in polling_action_cb
    updates = await self.bot.get_updates(
  File "/Users/alexandresimasmaciel/Library/Python/3.9/lib/python/site-packages/telegram/ext/_extbot.py", line 558, in get_updates
    updates = await super().get_updates(
  File "/Users/alexandresimasmaciel/Library/Python/3.9/lib/python/site-packages/telegram/_bot.py", line 525, in decorator
    result = await func(self, *args, **kwargs)  # skipcq: PYL-E1102
  File "/Users/alexandresimasmaciel/Library/Python/3.9/lib/python/site-packages/telegram/_bot.py", line 3584, in get_updates
    await self._post(
  File "/Users/alexandresimasmaciel/Library/Python/3.9/lib/python/site-packages/telegram/_bot.py", line 613, in _post
    return await self._do_post(
  File "/Users/alexandresimasmaciel/Library/Python/3.9/lib/python/site-packages/telegram/ext/_extbot.py", line 340, in _do_post
    return await super()._do_post(
  File "/Users/alexandresimasmaciel/Library/Python/3.9/lib/python/site-packages/telegram/_bot.py", line 641, in _do_post
    return await request.post(
  File "/Users/alexandresimasmaciel/Library/Python/3.9/lib/python/site-packages/telegram/request/_baserequest.py", line 200, in post
    result = await self._request_wrapper(
  File "/Users/alexandresimasmaciel/Library/Python/3.9/lib/python/site-packages/telegram/request/_baserequest.py", line 381, in _request_wrapper
    raise Conflict(message)
telegram.error.Conflict: Conflict: terminated by other getUpdates request; make sure that only one bot instance is running
2025-03-05 19:00:17 - telegram.ext.Updater - ERROR - Error while getting Updates: Conflict: terminated by other getUpdates request; make sure that only one bot instance is running
2025-03-05 19:00:17 - telegram.ext.Updater - ERROR - Exception happened while polling for updates.
Traceback (most recent call last):
  File "/Users/alexandresimasmaciel/Library/Python/3.9/lib/python/site-packages/telegram/ext/_updater.py", line 688, in _network_loop_retry
    if not await action_cb():
  File "/Users/alexandresimasmaciel/Library/Python/3.9/lib/python/site-packages/telegram/ext/_updater.py", line 384, in polling_action_cb
    raise exc
  File "/Users/alexandresimasmaciel/Library/Python/3.9/lib/python/site-packages/telegram/ext/_updater.py", line 373, in polling_action_cb
    updates = await self.bot.get_updates(
  File "/Users/alexandresimasmaciel/Library/Python/3.9/lib/python/site-packages/telegram/ext/_extbot.py", line 558, in get_updates
    updates = await super().get_updates(
  File "/Users/alexandresimasmaciel/Library/Python/3.9/lib/python/site-packages/telegram/_bot.py", line 525, in decorator
    result = await func(self, *args, **kwargs)  # skipcq: PYL-E1102
  File "/Users/alexandresimasmaciel/Library/Python/3.9/lib/python/site-packages/telegram/_bot.py", line 3584, in get_updates
    await self._post(
  File "/Users/alexandresimasmaciel/Library/Python/3.9/lib/python/site-packages/telegram/_bot.py", line 613, in _post
    return await self._do_post(
  File "/Users/alexandresimasmaciel/Library/Python/3.9/lib/python/site-packages/telegram/ext/_extbot.py", line 340, in _do_post
    return await super()._do_post(
  File "/Users/alexandresimasmaciel/Library/Python/3.9/lib/python/site-packages/telegram/_bot.py", line 641, in _do_post
    return await request.post(
  File "/Users/alexandresimasmaciel/Library/Python/3.9/lib/python/site-packages/telegram/request/_baserequest.py", line 200, in post
    result = await self._request_wrapper(
  File "/Users/alexandresimasmaciel/Library/Python/3.9/lib/python/site-packages/telegram/request/_baserequest.py", line 381, in _request_wrapper
    raise Conflict(message)
telegram.error.Conflict: Conflict: terminated by other getUpdates request; make sure that only one bot instance is running
2025-03-05 19:00:27 - root - ERROR - Sistema de logging inicializado (console: ERROR, arquivo: ERROR)
2025-03-05 19:00:29 - telegram.ext.Updater - ERROR - Error while getting Updates: Conflict: terminated by other getUpdates request; make sure that only one bot instance is running
2025-03-05 19:00:29 - telegram.ext.Updater - ERROR - Exception happened while polling for updates.
Traceback (most recent call last):
  File "/Users/alexandresimasmaciel/Library/Python/3.9/lib/python/site-packages/telegram/ext/_updater.py", line 688, in _network_loop_retry
    if not await action_cb():
  File "/Users/alexandresimasmaciel/Library/Python/3.9/lib/python/site-packages/telegram/ext/_updater.py", line 384, in polling_action_cb
    raise exc
  File "/Users/alexandresimasmaciel/Library/Python/3.9/lib/python/site-packages/telegram/ext/_updater.py", line 373, in polling_action_cb
    updates = await self.bot.get_updates(
  File "/Users/alexandresimasmaciel/Library/Python/3.9/lib/python/site-packages/telegram/ext/_extbot.py", line 558, in get_updates
    updates = await super().get_updates(
  File "/Users/alexandresimasmaciel/Library/Python/3.9/lib/python/site-packages/telegram/_bot.py", line 525, in decorator
    result = await func(self, *args, **kwargs)  # skipcq: PYL-E1102
  File "/Users/alexandresimasmaciel/Library/Python/3.9/lib/python/site-packages/telegram/_bot.py", line 3584, in get_updates
    await self._post(
  File "/Users/alexandresimasmaciel/Library/Python/3.9/lib/python/site-packages/telegram/_bot.py", line 613, in _post
    return await self._do_post(
  File "/Users/alexandresimasmaciel/Library/Python/3.9/lib/python/site-packages/telegram/ext/_extbot.py", line 340, in _do_post
    return await super()._do_post(
  File "/Users/alexandresimasmaciel/Library/Python/3.9/lib/python/site-packages/telegram/_bot.py", line 641, in _do_post
    return await request.post(
  File "/Users/alexandresimasmaciel/Library/Python/3.9/lib/python/site-packages/telegram/request/_baserequest.py", line 200, in post
    result = await self._request_wrapper(
  File "/Users/alexandresimasmaciel/Library/Python/3.9/lib/python/site-packages/telegram/request/_baserequest.py", line 381, in _request_wrapper
    raise Conflict(message)
telegram.error.Conflict: Conflict: terminated by other getUpdates request; make sure that only one bot instance is running
2025-03-05 19:00:40 - telegram.ext.Updater - ERROR - Error while getting Updates: Conflict: terminated by other getUpdates request; make sure that only one bot instance is running
2025-03-05 19:00:40 - telegram.ext.Updater - ERROR - Exception happened while polling for updates.
Traceback (most recent call last):
  File "/Users/alexandresimasmaciel/Library/Python/3.9/lib/python/site-packages/telegram/ext/_updater.py", line 688, in _network_loop_retry
    if not await action_cb():
  File "/Users/alexandresimasmaciel/Library/Python/3.9/lib/python/site-packages/telegram/ext/_updater.py", line 384, in polling_action_cb
    raise exc
  File "/Users/alexandresimasmaciel/Library/Python/3.9/lib/python/site-packages/telegram/ext/_updater.py", line 373, in polling_action_cb
    updates = await self.bot.get_updates(
  File "/Users/alexandresimasmaciel/Library/Python/3.9/lib/python/site-packages/telegram/ext/_extbot.py", line 558, in get_updates
    updates = await super().get_updates(
  File "/Users/alexandresimasmaciel/Library/Python/3.9/lib/python/site-packages/telegram/_bot.py", line 525, in decorator
    result = await func(self, *args, **kwargs)  # skipcq: PYL-E1102
  File "/Users/alexandresimasmaciel/Library/Python/3.9/lib/python/site-packages/telegram/_bot.py", line 3584, in get_updates
    await self._post(
  File "/Users/alexandresimasmaciel/Library/Python/3.9/lib/python/site-packages/telegram/_bot.py", line 613, in _post
    return await self._do_post(
  File "/Users/alexandresimasmaciel/Library/Python/3.9/lib/python/site-packages/telegram/ext/_extbot.py", line 340, in _do_post
    return await super()._do_post(
  File "/Users/alexandresimasmaciel/Library/Python/3.9/lib/python/site-packages/telegram/_bot.py", line 641, in _do_post
    return await request.post(
  File "/Users/alexandresimasmaciel/Library/Python/3.9/lib/python/site-packages/telegram/request/_baserequest.py", line 200, in post
    result = await self._request_wrapper(
  File "/Users/alexandresimasmaciel/Library/Python/3.9/lib/python/site-packages/telegram/request/_baserequest.py", line 381, in _request_wrapper
    raise Conflict(message)
telegram.error.Conflict: Conflict: terminated by other getUpdates request; make sure that only one bot instance is running
2025-03-05 19:00:44 - telegram.ext.Updater - ERROR - Error while getting Updates: Conflict: terminated by other getUpdates request; make sure that only one bot instance is running
2025-03-05 19:00:44 - telegram.ext.Updater - ERROR - Exception happened while polling for updates.
Traceback (most recent call last):
  File "/Users/alexandresimasmaciel/Library/Python/3.9/lib/python/site-packages/telegram/ext/_updater.py", line 688, in _network_loop_retry
    if not await action_cb():
  File "/Users/alexandresimasmaciel/Library/Python/3.9/lib/python/site-packages/telegram/ext/_updater.py", line 384, in polling_action_cb
    raise exc
  File "/Users/alexandresimasmaciel/Library/Python/3.9/lib/python/site-packages/telegram/ext/_updater.py", line 373, in polling_action_cb
    updates = await self.bot.get_updates(
  File "/Users/alexandresimasmaciel/Library/Python/3.9/lib/python/site-packages/telegram/ext/_extbot.py", line 558, in get_updates
    updates = await super().get_updates(
  File "/Users/alexandresimasmaciel/Library/Python/3.9/lib/python/site-packages/telegram/_bot.py", line 525, in decorator
    result = await func(self, *args, **kwargs)  # skipcq: PYL-E1102
  File "/Users/alexandresimasmaciel/Library/Python/3.9/lib/python/site-packages/telegram/_bot.py", line 3584, in get_updates
    await self._post(
  File "/Users/alexandresimasmaciel/Library/Python/3.9/lib/python/site-packages/telegram/_bot.py", line 613, in _post
    return await self._do_post(
  File "/Users/alexandresimasmaciel/Library/Python/3.9/lib/python/site-packages/telegram/ext/_extbot.py", line 340, in _do_post
    return await super()._do_post(
  File "/Users/alexandresimasmaciel/Library/Python/3.9/lib/python/site-packages/telegram/_bot.py", line 641, in _do_post
    return await request.post(
  File "/Users/alexandresimasmaciel/Library/Python/3.9/lib/python/site-packages/telegram/request/_baserequest.py", line 200, in post
    result = await self._request_wrapper(
  File "/Users/alexandresimasmaciel/Library/Python/3.9/lib/python/site-packages/telegram/request/_baserequest.py", line 381, in _request_wrapper
    raise Conflict(message)
telegram.error.Conflict: Conflict: terminated by other getUpdates request; make sure that only one bot instance is running
2025-03-05 19:00:44 - telegram.ext.Updater - ERROR - Error while getting Updates: Conflict: terminated by other getUpdates request; make sure that only one bot instance is running
2025-03-05 19:00:44 - telegram.ext.Updater - ERROR - Exception happened while polling for updates.
Traceback (most recent call last):
  File "/Users/alexandresimasmaciel/Library/Python/3.9/lib/python/site-packages/telegram/ext/_updater.py", line 688, in _network_loop_retry
    if not await action_cb():
  File "/Users/alexandresimasmaciel/Library/Python/3.9/lib/python/site-packages/telegram/ext/_updater.py", line 384, in polling_action_cb
    raise exc
  File "/Users/alexandresimasmaciel/Library/Python/3.9/lib/python/site-packages/telegram/ext/_updater.py", line 373, in polling_action_cb
    updates = await self.bot.get_updates(
  File "/Users/alexandresimasmaciel/Library/Python/3.9/lib/python/site-packages/telegram/ext/_extbot.py", line 558, in get_updates
    updates = await super().get_updates(
  File "/Users/alexandresimasmaciel/Library/Python/3.9/lib/python/site-packages/telegram/_bot.py", line 525, in decorator
    result = await func(self, *args, **kwargs)  # skipcq: PYL-E1102
  File "/Users/alexandresimasmaciel/Library/Python/3.9/lib/python/site-packages/telegram/_bot.py", line 3584, in get_updates
    await self._post(
  File "/Users/alexandresimasmaciel/Library/Python/3.9/lib/python/site-packages/telegram/_bot.py", line 613, in _post
    return await self._do_post(
  File "/Users/alexandresimasmaciel/Library/Python/3.9/lib/python/site-packages/telegram/ext/_extbot.py", line 340, in _do_post
    return await super()._do_post(
  File "/Users/alexandresimasmaciel/Library/Python/3.9/lib/python/site-packages/telegram/_bot.py", line 641, in _do_post
    return await request.post(
  File "/Users/alexandresimasmaciel/Library/Python/3.9/lib/python/site-packages/telegram/request/_baserequest.py", line 200, in post
    result = await self._request_wrapper(
  File "/Users/alexandresimasmaciel/Library/Python/3.9/lib/python/site-packages/telegram/request/_baserequest.py", line 381, in _request_wrapper
    raise Conflict(message)
telegram.error.Conflict: Conflict: terminated by other getUpdates request; make sure that only one bot instance is running
2025-03-05 19:00:45 - telegram.ext.Updater - ERROR - Error while getting Updates: Conflict: terminated by other getUpdates request; make sure that only one bot instance is running
2025-03-05 19:00:45 - telegram.ext.Updater - ERROR - Exception happened while polling for updates.
Traceback (most recent call last):
  File "/Users/alexandresimasmaciel/Library/Python/3.9/lib/python/site-packages/telegram/ext/_updater.py", line 688, in _network_loop_retry
    if not await action_cb():
  File "/Users/alexandresimasmaciel/Library/Python/3.9/lib/python/site-packages/telegram/ext/_updater.py", line 384, in polling_action_cb
    raise exc
  File "/Users/alexandresimasmaciel/Library/Python/3.9/lib/python/site-packages/telegram/ext/_updater.py", line 373, in polling_action_cb
    updates = await self.bot.get_updates(
  File "/Users/alexandresimasmaciel/Library/Python/3.9/lib/python/site-packages/telegram/ext/_extbot.py", line 558, in get_updates
    updates = await super().get_updates(
  File "/Users/alexandresimasmaciel/Library/Python/3.9/lib/python/site-packages/telegram/_bot.py", line 525, in decorator
    result = await func(self, *args, **kwargs)  # skipcq: PYL-E1102
  File "/Users/alexandresimasmaciel/Library/Python/3.9/lib/python/site-packages/telegram/_bot.py", line 3584, in get_updates
    await self._post(
  File "/Users/alexandresimasmaciel/Library/Python/3.9/lib/python/site-packages/telegram/_bot.py", line 613, in _post
    return await self._do_post(
  File "/Users/alexandresimasmaciel/Library/Python/3.9/lib/python/site-packages/telegram/ext/_extbot.py", line 340, in _do_post
    return await super()._do_post(
  File "/Users/alexandresimasmaciel/Library/Python/3.9/lib/python/site-packages/telegram/_bot.py", line 641, in _do_post
    return await request.post(
  File "/Users/alexandresimasmaciel/Library/Python/3.9/lib/python/site-packages/telegram/request/_baserequest.py", line 200, in post
    result = await self._request_wrapper(
  File "/Users/alexandresimasmaciel/Library/Python/3.9/lib/python/site-packages/telegram/request/_baserequest.py", line 381, in _request_wrapper
    raise Conflict(message)
telegram.error.Conflict: Conflict: terminated by other getUpdates request; make sure that only one bot instance is running
2025-03-05 19:00:49 - telegram.ext.Updater - ERROR - Error while getting Updates: Conflict: terminated by other getUpdates request; make sure that only one bot instance is running
2025-03-05 19:00:49 - telegram.ext.Updater - ERROR - Exception happened while polling for updates.
Traceback (most recent call last):
  File "/Users/alexandresimasmaciel/Library/Python/3.9/lib/python/site-packages/telegram/ext/_updater.py", line 688, in _network_loop_retry
    if not await action_cb():
  File "/Users/alexandresimasmaciel/Library/Python/3.9/lib/python/site-packages/telegram/ext/_updater.py", line 384, in polling_action_cb
    raise exc
  File "/Users/alexandresimasmaciel/Library/Python/3.9/lib/python/site-packages/telegram/ext/_updater.py", line 373, in polling_action_cb
    updates = await self.bot.get_updates(
  File "/Users/alexandresimasmaciel/Library/Python/3.9/lib/python/site-packages/telegram/ext/_extbot.py", line 558, in get_updates
    updates = await super().get_updates(
  File "/Users/alexandresimasmaciel/Library/Python/3.9/lib/python/site-packages/telegram/_bot.py", line 525, in decorator
    result = await func(self, *args, **kwargs)  # skipcq: PYL-E1102
  File "/Users/alexandresimasmaciel/Library/Python/3.9/lib/python/site-packages/telegram/_bot.py", line 3584, in get_updates
    await self._post(
  File "/Users/alexandresimasmaciel/Library/Python/3.9/lib/python/site-packages/telegram/_bot.py", line 613, in _post
    return await self._do_post(
  File "/Users/alexandresimasmaciel/Library/Python/3.9/lib/python/site-packages/telegram/ext/_extbot.py", line 340, in _do_post
    return await super()._do_post(
  File "/Users/alexandresimasmaciel/Library/Python/3.9/lib/python/site-packages/telegram/_bot.py", line 641, in _do_post
    return await request.post(
  File "/Users/alexandresimasmaciel/Library/Python/3.9/lib/python/site-packages/telegram/request/_baserequest.py", line 200, in post
    result = await self._request_wrapper(
  File "/Users/alexandresimasmaciel/Library/Python/3.9/lib/python/site-packages/telegram/request/_baserequest.py", line 381, in _request_wrapper
    raise Conflict(message)
telegram.error.Conflict: Conflict: terminated by other getUpdates request; make sure that only one bot instance is running
2025-03-05 19:01:02 - telegram.ext.Updater - ERROR - Error while getting Updates: Conflict: terminated by other getUpdates request; make sure that only one bot instance is running
2025-03-05 19:01:02 - telegram.ext.Updater - ERROR - Exception happened while polling for updates.
Traceback (most recent call last):
  File "/Users/alexandresimasmaciel/Library/Python/3.9/lib/python/site-packages/telegram/ext/_updater.py", line 688, in _network_loop_retry
    if not await action_cb():
  File "/Users/alexandresimasmaciel/Library/Python/3.9/lib/python/site-packages/telegram/ext/_updater.py", line 384, in polling_action_cb
    raise exc
  File "/Users/alexandresimasmaciel/Library/Python/3.9/lib/python/site-packages/telegram/ext/_updater.py", line 373, in polling_action_cb
    updates = await self.bot.get_updates(
  File "/Users/alexandresimasmaciel/Library/Python/3.9/lib/python/site-packages/telegram/ext/_extbot.py", line 558, in get_updates
    updates = await super().get_updates(
  File "/Users/alexandresimasmaciel/Library/Python/3.9/lib/python/site-packages/telegram/_bot.py", line 525, in decorator
    result = await func(self, *args, **kwargs)  # skipcq: PYL-E1102
  File "/Users/alexandresimasmaciel/Library/Python/3.9/lib/python/site-packages/telegram/_bot.py", line 3584, in get_updates
    await self._post(
  File "/Users/alexandresimasmaciel/Library/Python/3.9/lib/python/site-packages/telegram/_bot.py", line 613, in _post
    return await self._do_post(
  File "/Users/alexandresimasmaciel/Library/Python/3.9/lib/python/site-packages/telegram/ext/_extbot.py", line 340, in _do_post
    return await super()._do_post(
  File "/Users/alexandresimasmaciel/Library/Python/3.9/lib/python/site-packages/telegram/_bot.py", line 641, in _do_post
    return await request.post(
  File "/Users/alexandresimasmaciel/Library/Python/3.9/lib/python/site-packages/telegram/request/_baserequest.py", line 200, in post
    result = await self._request_wrapper(
  File "/Users/alexandresimasmaciel/Library/Python/3.9/lib/python/site-packages/telegram/request/_baserequest.py", line 381, in _request_wrapper
    raise Conflict(message)
telegram.error.Conflict: Conflict: terminated by other getUpdates request; make sure that only one bot instance is running
2025-03-05 19:01:06 - telegram.ext.Updater - ERROR - Error while getting Updates: Conflict: terminated by other getUpdates request; make sure that only one bot instance is running
2025-03-05 19:01:06 - telegram.ext.Updater - ERROR - Exception happened while polling for updates.
Traceback (most recent call last):
  File "/Users/alexandresimasmaciel/Library/Python/3.9/lib/python/site-packages/telegram/ext/_updater.py", line 688, in _network_loop_retry
    if not await action_cb():
  File "/Users/alexandresimasmaciel/Library/Python/3.9/lib/python/site-packages/telegram/ext/_updater.py", line 384, in polling_action_cb
    raise exc
  File "/Users/alexandresimasmaciel/Library/Python/3.9/lib/python/site-packages/telegram/ext/_updater.py", line 373, in polling_action_cb
    updates = await self.bot.get_updates(
  File "/Users/alexandresimasmaciel/Library/Python/3.9/lib/python/site-packages/telegram/ext/_extbot.py", line 558, in get_updates
    updates = await super().get_updates(
  File "/Users/alexandresimasmaciel/Library/Python/3.9/lib/python/site-packages/telegram/_bot.py", line 525, in decorator
    result = await func(self, *args, **kwargs)  # skipcq: PYL-E1102
  File "/Users/alexandresimasmaciel/Library/Python/3.9/lib/python/site-packages/telegram/_bot.py", line 3584, in get_updates
    await self._post(
  File "/Users/alexandresimasmaciel/Library/Python/3.9/lib/python/site-packages/telegram/_bot.py", line 613, in _post
    return await self._do_post(
  File "/Users/alexandresimasmaciel/Library/Python/3.9/lib/python/site-packages/telegram/ext/_extbot.py", line 340, in _do_post
    return await super()._do_post(
  File "/Users/alexandresimasmaciel/Library/Python/3.9/lib/python/site-packages/telegram/_bot.py", line 641, in _do_post
    return await request.post(
  File "/Users/alexandresimasmaciel/Library/Python/3.9/lib/python/site-packages/telegram/request/_baserequest.py", line 200, in post
    result = await self._request_wrapper(
  File "/Users/alexandresimasmaciel/Library/Python/3.9/lib/python/site-packages/telegram/request/_baserequest.py", line 381, in _request_wrapper
    raise Conflict(message)
telegram.error.Conflict: Conflict: terminated by other getUpdates request; make sure that only one bot instance is running
2025-03-05 19:01:15 - telegram.ext.Updater - ERROR - Error while getting Updates: Conflict: terminated by other getUpdates request; make sure that only one bot instance is running
2025-03-05 19:01:15 - telegram.ext.Updater - ERROR - Exception happened while polling for updates.
Traceback (most recent call last):
  File "/Users/alexandresimasmaciel/Library/Python/3.9/lib/python/site-packages/telegram/ext/_updater.py", line 688, in _network_loop_retry
    if not await action_cb():
  File "/Users/alexandresimasmaciel/Library/Python/3.9/lib/python/site-packages/telegram/ext/_updater.py", line 384, in polling_action_cb
    raise exc
  File "/Users/alexandresimasmaciel/Library/Python/3.9/lib/python/site-packages/telegram/ext/_updater.py", line 373, in polling_action_cb
    updates = await self.bot.get_updates(
  File "/Users/alexandresimasmaciel/Library/Python/3.9/lib/python/site-packages/telegram/ext/_extbot.py", line 558, in get_updates
    updates = await super().get_updates(
  File "/Users/alexandresimasmaciel/Library/Python/3.9/lib/python/site-packages/telegram/_bot.py", line 525, in decorator
    result = await func(self, *args, **kwargs)  # skipcq: PYL-E1102
  File "/Users/alexandresimasmaciel/Library/Python/3.9/lib/python/site-packages/telegram/_bot.py", line 3584, in get_updates
    await self._post(
  File "/Users/alexandresimasmaciel/Library/Python/3.9/lib/python/site-packages/telegram/_bot.py", line 613, in _post
    return await self._do_post(
  File "/Users/alexandresimasmaciel/Library/Python/3.9/lib/python/site-packages/telegram/ext/_extbot.py", line 340, in _do_post
    return await super()._do_post(
  File "/Users/alexandresimasmaciel/Library/Python/3.9/lib/python/site-packages/telegram/_bot.py", line 641, in _do_post
    return await request.post(
  File "/Users/alexandresimasmaciel/Library/Python/3.9/lib/python/site-packages/telegram/request/_baserequest.py", line 200, in post
    result = await self._request_wrapper(
  File "/Users/alexandresimasmaciel/Library/Python/3.9/lib/python/site-packages/telegram/request/_baserequest.py", line 381, in _request_wrapper
    raise Conflict(message)
telegram.error.Conflict: Conflict: terminated by other getUpdates request; make sure that only one bot instance is running
2025-03-05 19:01:19 - telegram.ext.Updater - ERROR - Error while getting Updates: Conflict: terminated by other getUpdates request; make sure that only one bot instance is running
2025-03-05 19:01:19 - telegram.ext.Updater - ERROR - Exception happened while polling for updates.
Traceback (most recent call last):
  File "/Users/alexandresimasmaciel/Library/Python/3.9/lib/python/site-packages/telegram/ext/_updater.py", line 688, in _network_loop_retry
    if not await action_cb():
  File "/Users/alexandresimasmaciel/Library/Python/3.9/lib/python/site-packages/telegram/ext/_updater.py", line 384, in polling_action_cb
    raise exc
  File "/Users/alexandresimasmaciel/Library/Python/3.9/lib/python/site-packages/telegram/ext/_updater.py", line 373, in polling_action_cb
    updates = await self.bot.get_updates(
  File "/Users/alexandresimasmaciel/Library/Python/3.9/lib/python/site-packages/telegram/ext/_extbot.py", line 558, in get_updates
    updates = await super().get_updates(
  File "/Users/alexandresimasmaciel/Library/Python/3.9/lib/python/site-packages/telegram/_bot.py", line 525, in decorator
    result = await func(self, *args, **kwargs)  # skipcq: PYL-E1102
  File "/Users/alexandresimasmaciel/Library/Python/3.9/lib/python/site-packages/telegram/_bot.py", line 3584, in get_updates
    await self._post(
  File "/Users/alexandresimasmaciel/Library/Python/3.9/lib/python/site-packages/telegram/_bot.py", line 613, in _post
    return await self._do_post(
  File "/Users/alexandresimasmaciel/Library/Python/3.9/lib/python/site-packages/telegram/ext/_extbot.py", line 340, in _do_post
    return await super()._do_post(
  File "/Users/alexandresimasmaciel/Library/Python/3.9/lib/python/site-packages/telegram/_bot.py", line 641, in _do_post
    return await request.post(
  File "/Users/alexandresimasmaciel/Library/Python/3.9/lib/python/site-packages/telegram/request/_baserequest.py", line 200, in post
    result = await self._request_wrapper(
  File "/Users/alexandresimasmaciel/Library/Python/3.9/lib/python/site-packages/telegram/request/_baserequest.py", line 381, in _request_wrapper
    raise Conflict(message)
telegram.error.Conflict: Conflict: terminated by other getUpdates request; make sure that only one bot instance is running
2025-03-05 19:01:20 - telegram.ext.Updater - ERROR - Error while getting Updates: Conflict: terminated by other getUpdates request; make sure that only one bot instance is running
2025-03-05 19:01:20 - telegram.ext.Updater - ERROR - Exception happened while polling for updates.
Traceback (most recent call last):
  File "/Users/alexandresimasmaciel/Library/Python/3.9/lib/python/site-packages/telegram/ext/_updater.py", line 688, in _network_loop_retry
    if not await action_cb():
  File "/Users/alexandresimasmaciel/Library/Python/3.9/lib/python/site-packages/telegram/ext/_updater.py", line 384, in polling_action_cb
    raise exc
  File "/Users/alexandresimasmaciel/Library/Python/3.9/lib/python/site-packages/telegram/ext/_updater.py", line 373, in polling_action_cb
    updates = await self.bot.get_updates(
  File "/Users/alexandresimasmaciel/Library/Python/3.9/lib/python/site-packages/telegram/ext/_extbot.py", line 558, in get_updates
    updates = await super().get_updates(
  File "/Users/alexandresimasmaciel/Library/Python/3.9/lib/python/site-packages/telegram/_bot.py", line 525, in decorator
    result = await func(self, *args, **kwargs)  # skipcq: PYL-E1102
  File "/Users/alexandresimasmaciel/Library/Python/3.9/lib/python/site-packages/telegram/_bot.py", line 3584, in get_updates
    await self._post(
  File "/Users/alexandresimasmaciel/Library/Python/3.9/lib/python/site-packages/telegram/_bot.py", line 613, in _post
    return await self._do_post(
  File "/Users/alexandresimasmaciel/Library/Python/3.9/lib/python/site-packages/telegram/ext/_extbot.py", line 340, in _do_post
    return await super()._do_post(
  File "/Users/alexandresimasmaciel/Library/Python/3.9/lib/python/site-packages/telegram/_bot.py", line 641, in _do_post
    return await request.post(
  File "/Users/alexandresimasmaciel/Library/Python/3.9/lib/python/site-packages/telegram/request/_baserequest.py", line 200, in post
    result = await self._request_wrapper(
  File "/Users/alexandresimasmaciel/Library/Python/3.9/lib/python/site-packages/telegram/request/_baserequest.py", line 381, in _request_wrapper
    raise Conflict(message)
telegram.error.Conflict: Conflict: terminated by other getUpdates request; make sure that only one bot instance is running
2025-03-05 19:01:25 - telegram.ext.Updater - ERROR - Error while getting Updates: Conflict: terminated by other getUpdates request; make sure that only one bot instance is running
2025-03-05 19:01:25 - telegram.ext.Updater - ERROR - Exception happened while polling for updates.
Traceback (most recent call last):
  File "/Users/alexandresimasmaciel/Library/Python/3.9/lib/python/site-packages/telegram/ext/_updater.py", line 688, in _network_loop_retry
    if not await action_cb():
  File "/Users/alexandresimasmaciel/Library/Python/3.9/lib/python/site-packages/telegram/ext/_updater.py", line 384, in polling_action_cb
    raise exc
  File "/Users/alexandresimasmaciel/Library/Python/3.9/lib/python/site-packages/telegram/ext/_updater.py", line 373, in polling_action_cb
    updates = await self.bot.get_updates(
  File "/Users/alexandresimasmaciel/Library/Python/3.9/lib/python/site-packages/telegram/ext/_extbot.py", line 558, in get_updates
    updates = await super().get_updates(
  File "/Users/alexandresimasmaciel/Library/Python/3.9/lib/python/site-packages/telegram/_bot.py", line 525, in decorator
    result = await func(self, *args, **kwargs)  # skipcq: PYL-E1102
  File "/Users/alexandresimasmaciel/Library/Python/3.9/lib/python/site-packages/telegram/_bot.py", line 3584, in get_updates
    await self._post(
  File "/Users/alexandresimasmaciel/Library/Python/3.9/lib/python/site-packages/telegram/_bot.py", line 613, in _post
    return await self._do_post(
  File "/Users/alexandresimasmaciel/Library/Python/3.9/lib/python/site-packages/telegram/ext/_extbot.py", line 340, in _do_post
    return await super()._do_post(
  File "/Users/alexandresimasmaciel/Library/Python/3.9/lib/python/site-packages/telegram/_bot.py", line 641, in _do_post
    return await request.post(
  File "/Users/alexandresimasmaciel/Library/Python/3.9/lib/python/site-packages/telegram/request/_baserequest.py", line 200, in post
    result = await self._request_wrapper(
  File "/Users/alexandresimasmaciel/Library/Python/3.9/lib/python/site-packages/telegram/request/_baserequest.py", line 381, in _request_wrapper
    raise Conflict(message)
telegram.error.Conflict: Conflict: terminated by other getUpdates request; make sure that only one bot instance is running
2025-03-05 19:01:26 - telegram.ext.Updater - ERROR - Error while getting Updates: Conflict: terminated by other getUpdates request; make sure that only one bot instance is running
2025-03-05 19:01:26 - telegram.ext.Updater - ERROR - Exception happened while polling for updates.
Traceback (most recent call last):
  File "/Users/alexandresimasmaciel/Library/Python/3.9/lib/python/site-packages/telegram/ext/_updater.py", line 688, in _network_loop_retry
    if not await action_cb():
  File "/Users/alexandresimasmaciel/Library/Python/3.9/lib/python/site-packages/telegram/ext/_updater.py", line 384, in polling_action_cb
    raise exc
  File "/Users/alexandresimasmaciel/Library/Python/3.9/lib/python/site-packages/telegram/ext/_updater.py", line 373, in polling_action_cb
    updates = await self.bot.get_updates(
  File "/Users/alexandresimasmaciel/Library/Python/3.9/lib/python/site-packages/telegram/ext/_extbot.py", line 558, in get_updates
    updates = await super().get_updates(
  File "/Users/alexandresimasmaciel/Library/Python/3.9/lib/python/site-packages/telegram/_bot.py", line 525, in decorator
    result = await func(self, *args, **kwargs)  # skipcq: PYL-E1102
  File "/Users/alexandresimasmaciel/Library/Python/3.9/lib/python/site-packages/telegram/_bot.py", line 3584, in get_updates
    await self._post(
  File "/Users/alexandresimasmaciel/Library/Python/3.9/lib/python/site-packages/telegram/_bot.py", line 613, in _post
    return await self._do_post(
  File "/Users/alexandresimasmaciel/Library/Python/3.9/lib/python/site-packages/telegram/ext/_extbot.py", line 340, in _do_post
    return await super()._do_post(
  File "/Users/alexandresimasmaciel/Library/Python/3.9/lib/python/site-packages/telegram/_bot.py", line 641, in _do_post
    return await request.post(
  File "/Users/alexandresimasmaciel/Library/Python/3.9/lib/python/site-packages/telegram/request/_baserequest.py", line 200, in post
    result = await self._request_wrapper(
  File "/Users/alexandresimasmaciel/Library/Python/3.9/lib/python/site-packages/telegram/request/_baserequest.py", line 381, in _request_wrapper
    raise Conflict(message)
telegram.error.Conflict: Conflict: terminated by other getUpdates request; make sure that only one bot instance is running
2025-03-05 19:01:32 - telegram.ext.Updater - ERROR - Error while getting Updates: Conflict: terminated by other getUpdates request; make sure that only one bot instance is running
2025-03-05 19:01:32 - telegram.ext.Updater - ERROR - Exception happened while polling for updates.
Traceback (most recent call last):
  File "/Users/alexandresimasmaciel/Library/Python/3.9/lib/python/site-packages/telegram/ext/_updater.py", line 688, in _network_loop_retry
    if not await action_cb():
  File "/Users/alexandresimasmaciel/Library/Python/3.9/lib/python/site-packages/telegram/ext/_updater.py", line 384, in polling_action_cb
    raise exc
  File "/Users/alexandresimasmaciel/Library/Python/3.9/lib/python/site-packages/telegram/ext/_updater.py", line 373, in polling_action_cb
    updates = await self.bot.get_updates(
  File "/Users/alexandresimasmaciel/Library/Python/3.9/lib/python/site-packages/telegram/ext/_extbot.py", line 558, in get_updates
    updates = await super().get_updates(
  File "/Users/alexandresimasmaciel/Library/Python/3.9/lib/python/site-packages/telegram/_bot.py", line 525, in decorator
    result = await func(self, *args, **kwargs)  # skipcq: PYL-E1102
  File "/Users/alexandresimasmaciel/Library/Python/3.9/lib/python/site-packages/telegram/_bot.py", line 3584, in get_updates
    await self._post(
  File "/Users/alexandresimasmaciel/Library/Python/3.9/lib/python/site-packages/telegram/_bot.py", line 613, in _post
    return await self._do_post(
  File "/Users/alexandresimasmaciel/Library/Python/3.9/lib/python/site-packages/telegram/ext/_extbot.py", line 340, in _do_post
    return await super()._do_post(
  File "/Users/alexandresimasmaciel/Library/Python/3.9/lib/python/site-packages/telegram/_bot.py", line 641, in _do_post
    return await request.post(
  File "/Users/alexandresimasmaciel/Library/Python/3.9/lib/python/site-packages/telegram/request/_baserequest.py", line 200, in post
    result = await self._request_wrapper(
  File "/Users/alexandresimasmaciel/Library/Python/3.9/lib/python/site-packages/telegram/request/_baserequest.py", line 381, in _request_wrapper
    raise Conflict(message)
telegram.error.Conflict: Conflict: terminated by other getUpdates request; make sure that only one bot instance is running
2025-03-05 19:01:33 - telegram.ext.Updater - ERROR - Error while getting Updates: Conflict: terminated by other getUpdates request; make sure that only one bot instance is running
2025-03-05 19:01:33 - telegram.ext.Updater - ERROR - Exception happened while polling for updates.
Traceback (most recent call last):
  File "/Users/alexandresimasmaciel/Library/Python/3.9/lib/python/site-packages/telegram/ext/_updater.py", line 688, in _network_loop_retry
    if not await action_cb():
  File "/Users/alexandresimasmaciel/Library/Python/3.9/lib/python/site-packages/telegram/ext/_updater.py", line 384, in polling_action_cb
    raise exc
  File "/Users/alexandresimasmaciel/Library/Python/3.9/lib/python/site-packages/telegram/ext/_updater.py", line 373, in polling_action_cb
    updates = await self.bot.get_updates(
  File "/Users/alexandresimasmaciel/Library/Python/3.9/lib/python/site-packages/telegram/ext/_extbot.py", line 558, in get_updates
    updates = await super().get_updates(
  File "/Users/alexandresimasmaciel/Library/Python/3.9/lib/python/site-packages/telegram/_bot.py", line 525, in decorator
    result = await func(self, *args, **kwargs)  # skipcq: PYL-E1102
  File "/Users/alexandresimasmaciel/Library/Python/3.9/lib/python/site-packages/telegram/_bot.py", line 3584, in get_updates
    await self._post(
  File "/Users/alexandresimasmaciel/Library/Python/3.9/lib/python/site-packages/telegram/_bot.py", line 613, in _post
    return await self._do_post(
  File "/Users/alexandresimasmaciel/Library/Python/3.9/lib/python/site-packages/telegram/ext/_extbot.py", line 340, in _do_post
    return await super()._do_post(
  File "/Users/alexandresimasmaciel/Library/Python/3.9/lib/python/site-packages/telegram/_bot.py", line 641, in _do_post
    return await request.post(
  File "/Users/alexandresimasmaciel/Library/Python/3.9/lib/python/site-packages/telegram/request/_baserequest.py", line 200, in post
    result = await self._request_wrapper(
  File "/Users/alexandresimasmaciel/Library/Python/3.9/lib/python/site-packages/telegram/request/_baserequest.py", line 381, in _request_wrapper
    raise Conflict(message)
telegram.error.Conflict: Conflict: terminated by other getUpdates request; make sure that only one bot instance is running
2025-03-05 19:01:36 - telegram.ext.Updater - ERROR - Error while getting Updates: Conflict: terminated by other getUpdates request; make sure that only one bot instance is running
2025-03-05 19:01:36 - telegram.ext.Updater - ERROR - Exception happened while polling for updates.
Traceback (most recent call last):
  File "/Users/alexandresimasmaciel/Library/Python/3.9/lib/python/site-packages/telegram/ext/_updater.py", line 688, in _network_loop_retry
    if not await action_cb():
  File "/Users/alexandresimasmaciel/Library/Python/3.9/lib/python/site-packages/telegram/ext/_updater.py", line 384, in polling_action_cb
    raise exc
  File "/Users/alexandresimasmaciel/Library/Python/3.9/lib/python/site-packages/telegram/ext/_updater.py", line 373, in polling_action_cb
    updates = await self.bot.get_updates(
  File "/Users/alexandresimasmaciel/Library/Python/3.9/lib/python/site-packages/telegram/ext/_extbot.py", line 558, in get_updates
    updates = await super().get_updates(
  File "/Users/alexandresimasmaciel/Library/Python/3.9/lib/python/site-packages/telegram/_bot.py", line 525, in decorator
    result = await func(self, *args, **kwargs)  # skipcq: PYL-E1102
  File "/Users/alexandresimasmaciel/Library/Python/3.9/lib/python/site-packages/telegram/_bot.py", line 3584, in get_updates
    await self._post(
  File "/Users/alexandresimasmaciel/Library/Python/3.9/lib/python/site-packages/telegram/_bot.py", line 613, in _post
    return await self._do_post(
  File "/Users/alexandresimasmaciel/Library/Python/3.9/lib/python/site-packages/telegram/ext/_extbot.py", line 340, in _do_post
    return await super()._do_post(
  File "/Users/alexandresimasmaciel/Library/Python/3.9/lib/python/site-packages/telegram/_bot.py", line 641, in _do_post
    return await request.post(
  File "/Users/alexandresimasmaciel/Library/Python/3.9/lib/python/site-packages/telegram/request/_baserequest.py", line 200, in post
    result = await self._request_wrapper(
  File "/Users/alexandresimasmaciel/Library/Python/3.9/lib/python/site-packages/telegram/request/_baserequest.py", line 381, in _request_wrapper
    raise Conflict(message)
telegram.error.Conflict: Conflict: terminated by other getUpdates request; make sure that only one bot instance is running
2025-03-05 19:01:36 - telegram.ext.Updater - ERROR - Error while getting Updates: Conflict: terminated by other getUpdates request; make sure that only one bot instance is running
2025-03-05 19:01:36 - telegram.ext.Updater - ERROR - Exception happened while polling for updates.
Traceback (most recent call last):
  File "/Users/alexandresimasmaciel/Library/Python/3.9/lib/python/site-packages/telegram/ext/_updater.py", line 688, in _network_loop_retry
    if not await action_cb():
  File "/Users/alexandresimasmaciel/Library/Python/3.9/lib/python/site-packages/telegram/ext/_updater.py", line 384, in polling_action_cb
    raise exc
  File "/Users/alexandresimasmaciel/Library/Python/3.9/lib/python/site-packages/telegram/ext/_updater.py", line 373, in polling_action_cb
    updates = await self.bot.get_updates(
  File "/Users/alexandresimasmaciel/Library/Python/3.9/lib/python/site-packages/telegram/ext/_extbot.py", line 558, in get_updates
    updates = await super().get_updates(
  File "/Users/alexandresimasmaciel/Library/Python/3.9/lib/python/site-packages/telegram/_bot.py", line 525, in decorator
    result = await func(self, *args, **kwargs)  # skipcq: PYL-E1102
  File "/Users/alexandresimasmaciel/Library/Python/3.9/lib/python/site-packages/telegram/_bot.py", line 3584, in get_updates
    await self._post(
  File "/Users/alexandresimasmaciel/Library/Python/3.9/lib/python/site-packages/telegram/_bot.py", line 613, in _post
    return await self._do_post(
  File "/Users/alexandresimasmaciel/Library/Python/3.9/lib/python/site-packages/telegram/ext/_extbot.py", line 340, in _do_post
    return await super()._do_post(
  File "/Users/alexandresimasmaciel/Library/Python/3.9/lib/python/site-packages/telegram/_bot.py", line 641, in _do_post
    return await request.post(
  File "/Users/alexandresimasmaciel/Library/Python/3.9/lib/python/site-packages/telegram/request/_baserequest.py", line 200, in post
    result = await self._request_wrapper(
  File "/Users/alexandresimasmaciel/Library/Python/3.9/lib/python/site-packages/telegram/request/_baserequest.py", line 381, in _request_wrapper
    raise Conflict(message)
telegram.error.Conflict: Conflict: terminated by other getUpdates request; make sure that only one bot instance is running
2025-03-05 19:01:42 - telegram.ext.Updater - ERROR - Error while getting Updates: Conflict: terminated by other getUpdates request; make sure that only one bot instance is running
2025-03-05 19:01:42 - telegram.ext.Updater - ERROR - Exception happened while polling for updates.
Traceback (most recent call last):
  File "/Users/alexandresimasmaciel/Library/Python/3.9/lib/python/site-packages/telegram/ext/_updater.py", line 688, in _network_loop_retry
    if not await action_cb():
  File "/Users/alexandresimasmaciel/Library/Python/3.9/lib/python/site-packages/telegram/ext/_updater.py", line 384, in polling_action_cb
    raise exc
  File "/Users/alexandresimasmaciel/Library/Python/3.9/lib/python/site-packages/telegram/ext/_updater.py", line 373, in polling_action_cb
    updates = await self.bot.get_updates(
  File "/Users/alexandresimasmaciel/Library/Python/3.9/lib/python/site-packages/telegram/ext/_extbot.py", line 558, in get_updates
    updates = await super().get_updates(
  File "/Users/alexandresimasmaciel/Library/Python/3.9/lib/python/site-packages/telegram/_bot.py", line 525, in decorator
    result = await func(self, *args, **kwargs)  # skipcq: PYL-E1102
  File "/Users/alexandresimasmaciel/Library/Python/3.9/lib/python/site-packages/telegram/_bot.py", line 3584, in get_updates
    await self._post(
  File "/Users/alexandresimasmaciel/Library/Python/3.9/lib/python/site-packages/telegram/_bot.py", line 613, in _post
    return await self._do_post(
  File "/Users/alexandresimasmaciel/Library/Python/3.9/lib/python/site-packages/telegram/ext/_extbot.py", line 340, in _do_post
    return await super()._do_post(
  File "/Users/alexandresimasmaciel/Library/Python/3.9/lib/python/site-packages/telegram/_bot.py", line 641, in _do_post
    return await request.post(
  File "/Users/alexandresimasmaciel/Library/Python/3.9/lib/python/site-packages/telegram/request/_baserequest.py", line 200, in post
    result = await self._request_wrapper(
  File "/Users/alexandresimasmaciel/Library/Python/3.9/lib/python/site-packages/telegram/request/_baserequest.py", line 381, in _request_wrapper
    raise Conflict(message)
telegram.error.Conflict: Conflict: terminated by other getUpdates request; make sure that only one bot instance is running
2025-03-05 19:01:48 - telegram.ext.Updater - ERROR - Error while getting Updates: Conflict: terminated by other getUpdates request; make sure that only one bot instance is running
2025-03-05 19:01:48 - telegram.ext.Updater - ERROR - Exception happened while polling for updates.
Traceback (most recent call last):
  File "/Users/alexandresimasmaciel/Library/Python/3.9/lib/python/site-packages/telegram/ext/_updater.py", line 688, in _network_loop_retry
    if not await action_cb():
  File "/Users/alexandresimasmaciel/Library/Python/3.9/lib/python/site-packages/telegram/ext/_updater.py", line 384, in polling_action_cb
    raise exc
  File "/Users/alexandresimasmaciel/Library/Python/3.9/lib/python/site-packages/telegram/ext/_updater.py", line 373, in polling_action_cb
    updates = await self.bot.get_updates(
  File "/Users/alexandresimasmaciel/Library/Python/3.9/lib/python/site-packages/telegram/ext/_extbot.py", line 558, in get_updates
    updates = await super().get_updates(
  File "/Users/alexandresimasmaciel/Library/Python/3.9/lib/python/site-packages/telegram/_bot.py", line 525, in decorator
    result = await func(self, *args, **kwargs)  # skipcq: PYL-E1102
  File "/Users/alexandresimasmaciel/Library/Python/3.9/lib/python/site-packages/telegram/_bot.py", line 3584, in get_updates
    await self._post(
  File "/Users/alexandresimasmaciel/Library/Python/3.9/lib/python/site-packages/telegram/_bot.py", line 613, in _post
    return await self._do_post(
  File "/Users/alexandresimasmaciel/Library/Python/3.9/lib/python/site-packages/telegram/ext/_extbot.py", line 340, in _do_post
    return await super()._do_post(
  File "/Users/alexandresimasmaciel/Library/Python/3.9/lib/python/site-packages/telegram/_bot.py", line 641, in _do_post
    return await request.post(
  File "/Users/alexandresimasmaciel/Library/Python/3.9/lib/python/site-packages/telegram/request/_baserequest.py", line 200, in post
    result = await self._request_wrapper(
  File "/Users/alexandresimasmaciel/Library/Python/3.9/lib/python/site-packages/telegram/request/_baserequest.py", line 381, in _request_wrapper
    raise Conflict(message)
telegram.error.Conflict: Conflict: terminated by other getUpdates request; make sure that only one bot instance is running
2025-03-05 19:01:51 - telegram.ext.Updater - ERROR - Error while getting Updates: Conflict: terminated by other getUpdates request; make sure that only one bot instance is running
2025-03-05 19:01:51 - telegram.ext.Updater - ERROR - Exception happened while polling for updates.
Traceback (most recent call last):
  File "/Users/alexandresimasmaciel/Library/Python/3.9/lib/python/site-packages/telegram/ext/_updater.py", line 688, in _network_loop_retry
    if not await action_cb():
  File "/Users/alexandresimasmaciel/Library/Python/3.9/lib/python/site-packages/telegram/ext/_updater.py", line 384, in polling_action_cb
    raise exc
  File "/Users/alexandresimasmaciel/Library/Python/3.9/lib/python/site-packages/telegram/ext/_updater.py", line 373, in polling_action_cb
    updates = await self.bot.get_updates(
  File "/Users/alexandresimasmaciel/Library/Python/3.9/lib/python/site-packages/telegram/ext/_extbot.py", line 558, in get_updates
    updates = await super().get_updates(
  File "/Users/alexandresimasmaciel/Library/Python/3.9/lib/python/site-packages/telegram/_bot.py", line 525, in decorator
    result = await func(self, *args, **kwargs)  # skipcq: PYL-E1102
  File "/Users/alexandresimasmaciel/Library/Python/3.9/lib/python/site-packages/telegram/_bot.py", line 3584, in get_updates
    await self._post(
  File "/Users/alexandresimasmaciel/Library/Python/3.9/lib/python/site-packages/telegram/_bot.py", line 613, in _post
    return await self._do_post(
  File "/Users/alexandresimasmaciel/Library/Python/3.9/lib/python/site-packages/telegram/ext/_extbot.py", line 340, in _do_post
    return await super()._do_post(
  File "/Users/alexandresimasmaciel/Library/Python/3.9/lib/python/site-packages/telegram/_bot.py", line 641, in _do_post
    return await request.post(
  File "/Users/alexandresimasmaciel/Library/Python/3.9/lib/python/site-packages/telegram/request/_baserequest.py", line 200, in post
    result = await self._request_wrapper(
  File "/Users/alexandresimasmaciel/Library/Python/3.9/lib/python/site-packages/telegram/request/_baserequest.py", line 381, in _request_wrapper
    raise Conflict(message)
telegram.error.Conflict: Conflict: terminated by other getUpdates request; make sure that only one bot instance is running
2025-03-05 19:01:53 - telegram.ext.Updater - ERROR - Error while getting Updates: Conflict: terminated by other getUpdates request; make sure that only one bot instance is running
2025-03-05 19:01:53 - telegram.ext.Updater - ERROR - Exception happened while polling for updates.
Traceback (most recent call last):
  File "/Users/alexandresimasmaciel/Library/Python/3.9/lib/python/site-packages/telegram/ext/_updater.py", line 688, in _network_loop_retry
    if not await action_cb():
  File "/Users/alexandresimasmaciel/Library/Python/3.9/lib/python/site-packages/telegram/ext/_updater.py", line 384, in polling_action_cb
    raise exc
  File "/Users/alexandresimasmaciel/Library/Python/3.9/lib/python/site-packages/telegram/ext/_updater.py", line 373, in polling_action_cb
    updates = await self.bot.get_updates(
  File "/Users/alexandresimasmaciel/Library/Python/3.9/lib/python/site-packages/telegram/ext/_extbot.py", line 558, in get_updates
    updates = await super().get_updates(
  File "/Users/alexandresimasmaciel/Library/Python/3.9/lib/python/site-packages/telegram/_bot.py", line 525, in decorator
    result = await func(self, *args, **kwargs)  # skipcq: PYL-E1102
  File "/Users/alexandresimasmaciel/Library/Python/3.9/lib/python/site-packages/telegram/_bot.py", line 3584, in get_updates
    await self._post(
  File "/Users/alexandresimasmaciel/Library/Python/3.9/lib/python/site-packages/telegram/_bot.py", line 613, in _post
    return await self._do_post(
  File "/Users/alexandresimasmaciel/Library/Python/3.9/lib/python/site-packages/telegram/ext/_extbot.py", line 340, in _do_post
    return await super()._do_post(
  File "/Users/alexandresimasmaciel/Library/Python/3.9/lib/python/site-packages/telegram/_bot.py", line 641, in _do_post
    return await request.post(
  File "/Users/alexandresimasmaciel/Library/Python/3.9/lib/python/site-packages/telegram/request/_baserequest.py", line 200, in post
    result = await self._request_wrapper(
  File "/Users/alexandresimasmaciel/Library/Python/3.9/lib/python/site-packages/telegram/request/_baserequest.py", line 381, in _request_wrapper
    raise Conflict(message)
telegram.error.Conflict: Conflict: terminated by other getUpdates request; make sure that only one bot instance is running
2025-03-05 19:02:02 - telegram.ext.Updater - ERROR - Error while getting Updates: Conflict: terminated by other getUpdates request; make sure that only one bot instance is running
2025-03-05 19:02:02 - telegram.ext.Updater - ERROR - Exception happened while polling for updates.
Traceback (most recent call last):
  File "/Users/alexandresimasmaciel/Library/Python/3.9/lib/python/site-packages/telegram/ext/_updater.py", line 688, in _network_loop_retry
    if not await action_cb():
  File "/Users/alexandresimasmaciel/Library/Python/3.9/lib/python/site-packages/telegram/ext/_updater.py", line 384, in polling_action_cb
    raise exc
  File "/Users/alexandresimasmaciel/Library/Python/3.9/lib/python/site-packages/telegram/ext/_updater.py", line 373, in polling_action_cb
    updates = await self.bot.get_updates(
  File "/Users/alexandresimasmaciel/Library/Python/3.9/lib/python/site-packages/telegram/ext/_extbot.py", line 558, in get_updates
    updates = await super().get_updates(
  File "/Users/alexandresimasmaciel/Library/Python/3.9/lib/python/site-packages/telegram/_bot.py", line 525, in decorator
    result = await func(self, *args, **kwargs)  # skipcq: PYL-E1102
  File "/Users/alexandresimasmaciel/Library/Python/3.9/lib/python/site-packages/telegram/_bot.py", line 3584, in get_updates
    await self._post(
  File "/Users/alexandresimasmaciel/Library/Python/3.9/lib/python/site-packages/telegram/_bot.py", line 613, in _post
    return await self._do_post(
  File "/Users/alexandresimasmaciel/Library/Python/3.9/lib/python/site-packages/telegram/ext/_extbot.py", line 340, in _do_post
    return await super()._do_post(
  File "/Users/alexandresimasmaciel/Library/Python/3.9/lib/python/site-packages/telegram/_bot.py", line 641, in _do_post
    return await request.post(
  File "/Users/alexandresimasmaciel/Library/Python/3.9/lib/python/site-packages/telegram/request/_baserequest.py", line 200, in post
    result = await self._request_wrapper(
  File "/Users/alexandresimasmaciel/Library/Python/3.9/lib/python/site-packages/telegram/request/_baserequest.py", line 381, in _request_wrapper
    raise Conflict(message)
telegram.error.Conflict: Conflict: terminated by other getUpdates request; make sure that only one bot instance is running
2025-03-05 19:02:06 - telegram.ext.Updater - ERROR - Error while getting Updates: Conflict: terminated by other getUpdates request; make sure that only one bot instance is running
2025-03-05 19:02:06 - telegram.ext.Updater - ERROR - Exception happened while polling for updates.
Traceback (most recent call last):
  File "/Users/alexandresimasmaciel/Library/Python/3.9/lib/python/site-packages/telegram/ext/_updater.py", line 688, in _network_loop_retry
    if not await action_cb():
  File "/Users/alexandresimasmaciel/Library/Python/3.9/lib/python/site-packages/telegram/ext/_updater.py", line 384, in polling_action_cb
    raise exc
  File "/Users/alexandresimasmaciel/Library/Python/3.9/lib/python/site-packages/telegram/ext/_updater.py", line 373, in polling_action_cb
    updates = await self.bot.get_updates(
  File "/Users/alexandresimasmaciel/Library/Python/3.9/lib/python/site-packages/telegram/ext/_extbot.py", line 558, in get_updates
    updates = await super().get_updates(
  File "/Users/alexandresimasmaciel/Library/Python/3.9/lib/python/site-packages/telegram/_bot.py", line 525, in decorator
    result = await func(self, *args, **kwargs)  # skipcq: PYL-E1102
  File "/Users/alexandresimasmaciel/Library/Python/3.9/lib/python/site-packages/telegram/_bot.py", line 3584, in get_updates
    await self._post(
  File "/Users/alexandresimasmaciel/Library/Python/3.9/lib/python/site-packages/telegram/_bot.py", line 613, in _post
    return await self._do_post(
  File "/Users/alexandresimasmaciel/Library/Python/3.9/lib/python/site-packages/telegram/ext/_extbot.py", line 340, in _do_post
    return await super()._do_post(
  File "/Users/alexandresimasmaciel/Library/Python/3.9/lib/python/site-packages/telegram/_bot.py", line 641, in _do_post
    return await request.post(
  File "/Users/alexandresimasmaciel/Library/Python/3.9/lib/python/site-packages/telegram/request/_baserequest.py", line 200, in post
    result = await self._request_wrapper(
  File "/Users/alexandresimasmaciel/Library/Python/3.9/lib/python/site-packages/telegram/request/_baserequest.py", line 381, in _request_wrapper
    raise Conflict(message)
telegram.error.Conflict: Conflict: terminated by other getUpdates request; make sure that only one bot instance is running
2025-03-05 19:02:07 - telegram.ext.Updater - ERROR - Error while getting Updates: Conflict: terminated by other getUpdates request; make sure that only one bot instance is running
2025-03-05 19:02:07 - telegram.ext.Updater - ERROR - Exception happened while polling for updates.
Traceback (most recent call last):
  File "/Users/alexandresimasmaciel/Library/Python/3.9/lib/python/site-packages/telegram/ext/_updater.py", line 688, in _network_loop_retry
    if not await action_cb():
  File "/Users/alexandresimasmaciel/Library/Python/3.9/lib/python/site-packages/telegram/ext/_updater.py", line 384, in polling_action_cb
    raise exc
  File "/Users/alexandresimasmaciel/Library/Python/3.9/lib/python/site-packages/telegram/ext/_updater.py", line 373, in polling_action_cb
    updates = await self.bot.get_updates(
  File "/Users/alexandresimasmaciel/Library/Python/3.9/lib/python/site-packages/telegram/ext/_extbot.py", line 558, in get_updates
    updates = await super().get_updates(
  File "/Users/alexandresimasmaciel/Library/Python/3.9/lib/python/site-packages/telegram/_bot.py", line 525, in decorator
    result = await func(self, *args, **kwargs)  # skipcq: PYL-E1102
  File "/Users/alexandresimasmaciel/Library/Python/3.9/lib/python/site-packages/telegram/_bot.py", line 3584, in get_updates
    await self._post(
  File "/Users/alexandresimasmaciel/Library/Python/3.9/lib/python/site-packages/telegram/_bot.py", line 613, in _post
    return await self._do_post(
  File "/Users/alexandresimasmaciel/Library/Python/3.9/lib/python/site-packages/telegram/ext/_extbot.py", line 340, in _do_post
    return await super()._do_post(
  File "/Users/alexandresimasmaciel/Library/Python/3.9/lib/python/site-packages/telegram/_bot.py", line 641, in _do_post
    return await request.post(
  File "/Users/alexandresimasmaciel/Library/Python/3.9/lib/python/site-packages/telegram/request/_baserequest.py", line 200, in post
    result = await self._request_wrapper(
  File "/Users/alexandresimasmaciel/Library/Python/3.9/lib/python/site-packages/telegram/request/_baserequest.py", line 381, in _request_wrapper
    raise Conflict(message)
telegram.error.Conflict: Conflict: terminated by other getUpdates request; make sure that only one bot instance is running
2025-03-05 19:02:12 - telegram.ext.Updater - ERROR - Error while getting Updates: Conflict: terminated by other getUpdates request; make sure that only one bot instance is running
2025-03-05 19:02:12 - telegram.ext.Updater - ERROR - Exception happened while polling for updates.
Traceback (most recent call last):
  File "/Users/alexandresimasmaciel/Library/Python/3.9/lib/python/site-packages/telegram/ext/_updater.py", line 688, in _network_loop_retry
    if not await action_cb():
  File "/Users/alexandresimasmaciel/Library/Python/3.9/lib/python/site-packages/telegram/ext/_updater.py", line 384, in polling_action_cb
    raise exc
  File "/Users/alexandresimasmaciel/Library/Python/3.9/lib/python/site-packages/telegram/ext/_updater.py", line 373, in polling_action_cb
    updates = await self.bot.get_updates(
  File "/Users/alexandresimasmaciel/Library/Python/3.9/lib/python/site-packages/telegram/ext/_extbot.py", line 558, in get_updates
    updates = await super().get_updates(
  File "/Users/alexandresimasmaciel/Library/Python/3.9/lib/python/site-packages/telegram/_bot.py", line 525, in decorator
    result = await func(self, *args, **kwargs)  # skipcq: PYL-E1102
  File "/Users/alexandresimasmaciel/Library/Python/3.9/lib/python/site-packages/telegram/_bot.py", line 3584, in get_updates
    await self._post(
  File "/Users/alexandresimasmaciel/Library/Python/3.9/lib/python/site-packages/telegram/_bot.py", line 613, in _post
    return await self._do_post(
  File "/Users/alexandresimasmaciel/Library/Python/3.9/lib/python/site-packages/telegram/ext/_extbot.py", line 340, in _do_post
    return await super()._do_post(
  File "/Users/alexandresimasmaciel/Library/Python/3.9/lib/python/site-packages/telegram/_bot.py", line 641, in _do_post
    return await request.post(
  File "/Users/alexandresimasmaciel/Library/Python/3.9/lib/python/site-packages/telegram/request/_baserequest.py", line 200, in post
    result = await self._request_wrapper(
  File "/Users/alexandresimasmaciel/Library/Python/3.9/lib/python/site-packages/telegram/request/_baserequest.py", line 381, in _request_wrapper
    raise Conflict(message)
telegram.error.Conflict: Conflict: terminated by other getUpdates request; make sure that only one bot instance is running
2025-03-05 19:02:18 - telegram.ext.Updater - ERROR - Error while getting Updates: Conflict: terminated by other getUpdates request; make sure that only one bot instance is running
2025-03-05 19:02:18 - telegram.ext.Updater - ERROR - Exception happened while polling for updates.
Traceback (most recent call last):
  File "/Users/alexandresimasmaciel/Library/Python/3.9/lib/python/site-packages/telegram/ext/_updater.py", line 688, in _network_loop_retry
    if not await action_cb():
  File "/Users/alexandresimasmaciel/Library/Python/3.9/lib/python/site-packages/telegram/ext/_updater.py", line 384, in polling_action_cb
    raise exc
  File "/Users/alexandresimasmaciel/Library/Python/3.9/lib/python/site-packages/telegram/ext/_updater.py", line 373, in polling_action_cb
    updates = await self.bot.get_updates(
  File "/Users/alexandresimasmaciel/Library/Python/3.9/lib/python/site-packages/telegram/ext/_extbot.py", line 558, in get_updates
    updates = await super().get_updates(
  File "/Users/alexandresimasmaciel/Library/Python/3.9/lib/python/site-packages/telegram/_bot.py", line 525, in decorator
    result = await func(self, *args, **kwargs)  # skipcq: PYL-E1102
  File "/Users/alexandresimasmaciel/Library/Python/3.9/lib/python/site-packages/telegram/_bot.py", line 3584, in get_updates
    await self._post(
  File "/Users/alexandresimasmaciel/Library/Python/3.9/lib/python/site-packages/telegram/_bot.py", line 613, in _post
    return await self._do_post(
  File "/Users/alexandresimasmaciel/Library/Python/3.9/lib/python/site-packages/telegram/ext/_extbot.py", line 340, in _do_post
    return await super()._do_post(
  File "/Users/alexandresimasmaciel/Library/Python/3.9/lib/python/site-packages/telegram/_bot.py", line 641, in _do_post
    return await request.post(
  File "/Users/alexandresimasmaciel/Library/Python/3.9/lib/python/site-packages/telegram/request/_baserequest.py", line 200, in post
    result = await self._request_wrapper(
  File "/Users/alexandresimasmaciel/Library/Python/3.9/lib/python/site-packages/telegram/request/_baserequest.py", line 381, in _request_wrapper
    raise Conflict(message)
telegram.error.Conflict: Conflict: terminated by other getUpdates request; make sure that only one bot instance is running
2025-03-05 19:02:22 - telegram.ext.Updater - ERROR - Error while getting Updates: Conflict: terminated by other getUpdates request; make sure that only one bot instance is running
2025-03-05 19:02:22 - telegram.ext.Updater - ERROR - Exception happened while polling for updates.
Traceback (most recent call last):
  File "/Users/alexandresimasmaciel/Library/Python/3.9/lib/python/site-packages/telegram/ext/_updater.py", line 688, in _network_loop_retry
    if not await action_cb():
  File "/Users/alexandresimasmaciel/Library/Python/3.9/lib/python/site-packages/telegram/ext/_updater.py", line 384, in polling_action_cb
    raise exc
  File "/Users/alexandresimasmaciel/Library/Python/3.9/lib/python/site-packages/telegram/ext/_updater.py", line 373, in polling_action_cb
    updates = await self.bot.get_updates(
  File "/Users/alexandresimasmaciel/Library/Python/3.9/lib/python/site-packages/telegram/ext/_extbot.py", line 558, in get_updates
    updates = await super().get_updates(
  File "/Users/alexandresimasmaciel/Library/Python/3.9/lib/python/site-packages/telegram/_bot.py", line 525, in decorator
    result = await func(self, *args, **kwargs)  # skipcq: PYL-E1102
  File "/Users/alexandresimasmaciel/Library/Python/3.9/lib/python/site-packages/telegram/_bot.py", line 3584, in get_updates
    await self._post(
  File "/Users/alexandresimasmaciel/Library/Python/3.9/lib/python/site-packages/telegram/_bot.py", line 613, in _post
    return await self._do_post(
  File "/Users/alexandresimasmaciel/Library/Python/3.9/lib/python/site-packages/telegram/ext/_extbot.py", line 340, in _do_post
    return await super()._do_post(
  File "/Users/alexandresimasmaciel/Library/Python/3.9/lib/python/site-packages/telegram/_bot.py", line 641, in _do_post
    return await request.post(
  File "/Users/alexandresimasmaciel/Library/Python/3.9/lib/python/site-packages/telegram/request/_baserequest.py", line 200, in post
    result = await self._request_wrapper(
  File "/Users/alexandresimasmaciel/Library/Python/3.9/lib/python/site-packages/telegram/request/_baserequest.py", line 381, in _request_wrapper
    raise Conflict(message)
telegram.error.Conflict: Conflict: terminated by other getUpdates request; make sure that only one bot instance is running
2025-03-05 19:02:24 - telegram.ext.Updater - ERROR - Error while getting Updates: Conflict: terminated by other getUpdates request; make sure that only one bot instance is running
2025-03-05 19:02:24 - telegram.ext.Updater - ERROR - Exception happened while polling for updates.
Traceback (most recent call last):
  File "/Users/alexandresimasmaciel/Library/Python/3.9/lib/python/site-packages/telegram/ext/_updater.py", line 688, in _network_loop_retry
    if not await action_cb():
  File "/Users/alexandresimasmaciel/Library/Python/3.9/lib/python/site-packages/telegram/ext/_updater.py", line 384, in polling_action_cb
    raise exc
  File "/Users/alexandresimasmaciel/Library/Python/3.9/lib/python/site-packages/telegram/ext/_updater.py", line 373, in polling_action_cb
    updates = await self.bot.get_updates(
  File "/Users/alexandresimasmaciel/Library/Python/3.9/lib/python/site-packages/telegram/ext/_extbot.py", line 558, in get_updates
    updates = await super().get_updates(
  File "/Users/alexandresimasmaciel/Library/Python/3.9/lib/python/site-packages/telegram/_bot.py", line 525, in decorator
    result = await func(self, *args, **kwargs)  # skipcq: PYL-E1102
  File "/Users/alexandresimasmaciel/Library/Python/3.9/lib/python/site-packages/telegram/_bot.py", line 3584, in get_updates
    await self._post(
  File "/Users/alexandresimasmaciel/Library/Python/3.9/lib/python/site-packages/telegram/_bot.py", line 613, in _post
    return await self._do_post(
  File "/Users/alexandresimasmaciel/Library/Python/3.9/lib/python/site-packages/telegram/ext/_extbot.py", line 340, in _do_post
    return await super()._do_post(
  File "/Users/alexandresimasmaciel/Library/Python/3.9/lib/python/site-packages/telegram/_bot.py", line 641, in _do_post
    return await request.post(
  File "/Users/alexandresimasmaciel/Library/Python/3.9/lib/python/site-packages/telegram/request/_baserequest.py", line 200, in post
    result = await self._request_wrapper(
  File "/Users/alexandresimasmaciel/Library/Python/3.9/lib/python/site-packages/telegram/request/_baserequest.py", line 381, in _request_wrapper
    raise Conflict(message)
telegram.error.Conflict: Conflict: terminated by other getUpdates request; make sure that only one bot instance is running
2025-03-05 19:02:26 - telegram.ext.Updater - ERROR - Error while getting Updates: Conflict: terminated by other getUpdates request; make sure that only one bot instance is running
2025-03-05 19:02:26 - telegram.ext.Updater - ERROR - Exception happened while polling for updates.
Traceback (most recent call last):
  File "/Users/alexandresimasmaciel/Library/Python/3.9/lib/python/site-packages/telegram/ext/_updater.py", line 688, in _network_loop_retry
    if not await action_cb():
  File "/Users/alexandresimasmaciel/Library/Python/3.9/lib/python/site-packages/telegram/ext/_updater.py", line 384, in polling_action_cb
    raise exc
  File "/Users/alexandresimasmaciel/Library/Python/3.9/lib/python/site-packages/telegram/ext/_updater.py", line 373, in polling_action_cb
    updates = await self.bot.get_updates(
  File "/Users/alexandresimasmaciel/Library/Python/3.9/lib/python/site-packages/telegram/ext/_extbot.py", line 558, in get_updates
    updates = await super().get_updates(
  File "/Users/alexandresimasmaciel/Library/Python/3.9/lib/python/site-packages/telegram/_bot.py", line 525, in decorator
    result = await func(self, *args, **kwargs)  # skipcq: PYL-E1102
  File "/Users/alexandresimasmaciel/Library/Python/3.9/lib/python/site-packages/telegram/_bot.py", line 3584, in get_updates
    await self._post(
  File "/Users/alexandresimasmaciel/Library/Python/3.9/lib/python/site-packages/telegram/_bot.py", line 613, in _post
    return await self._do_post(
  File "/Users/alexandresimasmaciel/Library/Python/3.9/lib/python/site-packages/telegram/ext/_extbot.py", line 340, in _do_post
    return await super()._do_post(
  File "/Users/alexandresimasmaciel/Library/Python/3.9/lib/python/site-packages/telegram/_bot.py", line 641, in _do_post
    return await request.post(
  File "/Users/alexandresimasmaciel/Library/Python/3.9/lib/python/site-packages/telegram/request/_baserequest.py", line 200, in post
    result = await self._request_wrapper(
  File "/Users/alexandresimasmaciel/Library/Python/3.9/lib/python/site-packages/telegram/request/_baserequest.py", line 381, in _request_wrapper
    raise Conflict(message)
telegram.error.Conflict: Conflict: terminated by other getUpdates request; make sure that only one bot instance is running
